Workbook
Name E_BIT: TABLES!$A$32:$G$39
Name INV_IP: TABLES!$A$100:$I$107
Name IP: TABLES!$A$22:$I$29
Name MESSAGE: 'AVALANCHE EFFECT'!$GT$2:$GW$19
Name P: TABLES!$H$90:$L$97
Name PC_1: TABLES!$A$2:$H$9
Name PC_2: TABLES!$A$12:$G$19
Name RL: 'IO SHEET'!$U$27:$X$43
Name S1_BOX: TABLES!$A$42:$Q$45
Name S2_BOX: TABLES!$A$48:$Q$51
Name S3_BOX: TABLES!$A$54:$Q$57
Name S4_BOX: TABLES!$A$60:$Q$63
Name S5_BOX: TABLES!$A$66:$Q$69
Name S6_BOX: TABLES!$A$72:$Q$75
Name S7_BOX: TABLES!$A$78:$Q$81
Name S8_BOX: TABLES!$A$84:$Q$87

Sheet IO SHEET
B1: 1 | C1: 2 | D1: 3 | E1: 4 | F1: 5 | G1: 6 | H1: 7 | I1: 8 | J1: 9 | K1: 10 | L1: 11 | M1: 12 | N1: 13 | O1: 14 | P1: 15 | Q1: 16
A3: MESSAGE (X) | B3: 1 | C3: 2 | D3: 3 | E3: 4 | F3: 5 | G3: 6 | H3: A | I3: B | J3: C | K3: D | L3: 1 | M3: 3 | N3: 2 | O3: 5 | P3: 3 | Q3: 6 | S3: ITERATION | V3: 16 | W3: <<INPUT NUMBER OF ITERATIONS FOR Ri
A4: Xbin | B4: =HEX2BIN(B3,4) -> 0001 | C4: =HEX2BIN(C3,4) -> 0010 | D4: =HEX2BIN(D3,4) -> 0011 | E4: =HEX2BIN(E3,4) -> 0100 | F4: =HEX2BIN(F3,4) -> 0101 | G4: =HEX2BIN(G3,4) -> 0110 | H4: =HEX2BIN(H3,4) -> 1010 | I4: =HEX2BIN(I3,4) -> 1011 | ... Q4: =HEX2BIN(Q3,4) -> 0110 | S4: =U47 -> R16||L16 | V4: =X47 -> 0001100110111010100100100001001011001111001001101011010001110010
A5: Xstr | B5: =CONCATENATE(B4,C4,D4,E4,F4,G4,H4,I4,J4,K4,L4,M4,N4,O4,P4,Q4) -> 0001001000110100010101101010101111001101000100110010010100110110
A6: L | B6: =LEFT(B5,32) -> 00010010001101000101011010101011 | S6: CYPHERTEXT MESSAGE (Y)
A7: R | B7: =RIGHT(B5,32) -> 11001101000100110010010100110110 | W7: Y(HEX) | Y7: = | Z7: =AB61 -> C0B7A8D05F3A829C
W8: Y(BIN) | Y8: = | Z8: =AB62 -> 1100000010110111101010001101000001011111001110101000001010011100
A9: KEY (K) | B9: A | C9: A | D9: B | E9: B | F9: 0 | G9: 9 | H9: 1 | I9: 8 | J9: 2 | K9: 7 | L9: 3 | M9: 6 | N9: C | O9: C | P9: D | Q9: D
A10: Kbin | B10: =HEX2BIN(B9,4) -> 1010 | C10: =HEX2BIN(C9,4) -> 1010 | D10: =HEX2BIN(D9,4) -> 1011 | E10: =HEX2BIN(E9,4) -> 1011 | F10: =HEX2BIN(F9,4) -> 0000 | G10: =HEX2BIN(G9,4) -> 1001 | H10: =HEX2BIN(H9,4) -> 0001 | I10: =HEX2BIN(I9,4) -> 1000 | ... Q10: =HEX2BIN(Q9,4) -> 1101
A11: kstr | B11: =CONCATENATE(B10,C10,D10,E10,F10,G10,H10,I10,J10,K10,L10,M10,N10,O10,P10,Q10) -> 1010101010111011000010010001100000100111001101101100110011011101
C13: 1 | D13: 2 | E13: 3 | F13: 4 | G13: 5 | H13: 6 | I13: 7 | J13: 8 | T13: 3 | U13: 5 | V13: 7 | W13: 0 | X13: E | Y13: 2 | Z13: F | AA13: 1 | AB13: B | AC13: A | AD13: 4 | AE13: 6 | AF13: 8 | AG13: 2 | AH13: C | AI13: 7
A14: MIP | B14: 1 | C14: =MID($B$5,VLOOKUP($B14,IP,C$13+1,FALSE),1) -> 0 | D14: =MID($B$5,VLOOKUP($B14,IP,D$13+1,FALSE),1) -> 0 | E14: =MID($B$5,VLOOKUP($B14,IP,E$13+1,FALSE),1) -> 0 | F14: =MID($B$5,VLOOKUP($B14,IP,F$13+1,FALSE),1) -> 1 | G14: =MID($B$5,VLOOKUP($B14,IP,G$13+1,FALSE),1) -> 0 | H14: =MID($B$5,VLOOKUP($B14,IP,H$13+1,FALSE),1) -> 1 | I14: =MID($B$5,VLOOKUP($B14,IP,I$13+1,FALSE),1) -> 0 | J14: =MID($B$5,VLOOKUP($B14,IP,J$13+1,FALSE),1) -> 0 | K14: =CONCATENATE(C14,D14,E14,F14,G14,H14,I14,J14) -> 00010100
B15: 2 | C15: =MID($B$5,VLOOKUP($B15,IP,C$13+1,FALSE),1) -> 1 | D15: =MID($B$5,VLOOKUP($B15,IP,D$13+1,FALSE),1) -> 0 | E15: =MID($B$5,VLOOKUP($B15,IP,E$13+1,FALSE),1) -> 1 | F15: =MID($B$5,VLOOKUP($B15,IP,F$13+1,FALSE),1) -> 0 | G15: =MID($B$5,VLOOKUP($B15,IP,G$13+1,FALSE),1) -> 0 | H15: =MID($B$5,VLOOKUP($B15,IP,H$13+1,FALSE),1) -> 1 | I15: =MID($B$5,VLOOKUP($B15,IP,I$13+1,FALSE),1) -> 1 | J15: =MID($B$5,VLOOKUP($B15,IP,J$13+1,FALSE),1) -> 1 | K15: =CONCATENATE(C15,D15,E15,F15,G15,H15,I15,J15) -> 10100111
B16: 3 | C16: =MID($B$5,VLOOKUP($B16,IP,C$13+1,FALSE),1) -> 1 | D16: =MID($B$5,VLOOKUP($B16,IP,D$13+1,FALSE),1) -> 1 | E16: =MID($B$5,VLOOKUP($B16,IP,E$13+1,FALSE),1) -> 0 | F16: =MID($B$5,VLOOKUP($B16,IP,F$13+1,FALSE),1) -> 1 | G16: =MID($B$5,VLOOKUP($B16,IP,G$13+1,FALSE),1) -> 0 | H16: =MID($B$5,VLOOKUP($B16,IP,H$13+1,FALSE),1) -> 1 | I16: =MID($B$5,VLOOKUP($B16,IP,I$13+1,FALSE),1) -> 1 | J16: =MID($B$5,VLOOKUP($B16,IP,J$13+1,FALSE),1) -> 0 | K16: =CONCATENATE(C16,D16,E16,F16,G16,H16,I16,J16) -> 11010110
B17: 4 | C17: =MID($B$5,VLOOKUP($B17,IP,C$13+1,FALSE),1) -> 0 | D17: =MID($B$5,VLOOKUP($B17,IP,D$13+1,FALSE),1) -> 1 | E17: =MID($B$5,VLOOKUP($B17,IP,E$13+1,FALSE),1) -> 1 | F17: =MID($B$5,VLOOKUP($B17,IP,F$13+1,FALSE),1) -> 1 | G17: =MID($B$5,VLOOKUP($B17,IP,G$13+1,FALSE),1) -> 1 | H17: =MID($B$5,VLOOKUP($B17,IP,H$13+1,FALSE),1) -> 0 | I17: =MID($B$5,VLOOKUP($B17,IP,I$13+1,FALSE),1) -> 0 | J17: =MID($B$5,VLOOKUP($B17,IP,J$13+1,FALSE),1) -> 0 | K17: =CONCATENATE(C17,D17,E17,F17,G17,H17,I17,J17) -> 01111000
B18: 5 | C18: =MID($B$5,VLOOKUP($B18,IP,C$13+1,FALSE),1) -> 0 | D18: =MID($B$5,VLOOKUP($B18,IP,D$13+1,FALSE),1) -> 0 | E18: =MID($B$5,VLOOKUP($B18,IP,E$13+1,FALSE),1) -> 0 | F18: =MID($B$5,VLOOKUP($B18,IP,F$13+1,FALSE),1) -> 1 | G18: =MID($B$5,VLOOKUP($B18,IP,G$13+1,FALSE),1) -> 1 | H18: =MID($B$5,VLOOKUP($B18,IP,H$13+1,FALSE),1) -> 0 | I18: =MID($B$5,VLOOKUP($B18,IP,I$13+1,FALSE),1) -> 0 | J18: =MID($B$5,VLOOKUP($B18,IP,J$13+1,FALSE),1) -> 0 | K18: =CONCATENATE(C18,D18,E18,F18,G18,H18,I18,J18) -> 00011000
B19: 6 | C19: =MID($B$5,VLOOKUP($B19,IP,C$13+1,FALSE),1) -> 1 | D19: =MID($B$5,VLOOKUP($B19,IP,D$13+1,FALSE),1) -> 1 | E19: =MID($B$5,VLOOKUP($B19,IP,E$13+1,FALSE),1) -> 0 | F19: =MID($B$5,VLOOKUP($B19,IP,F$13+1,FALSE),1) -> 0 | G19: =MID($B$5,VLOOKUP($B19,IP,G$13+1,FALSE),1) -> 1 | H19: =MID($B$5,VLOOKUP($B19,IP,H$13+1,FALSE),1) -> 0 | I19: =MID($B$5,VLOOKUP($B19,IP,I$13+1,FALSE),1) -> 1 | J19: =MID($B$5,VLOOKUP($B19,IP,J$13+1,FALSE),1) -> 0 | K19: =CONCATENATE(C19,D19,E19,F19,G19,H19,I19,J19) -> 11001010
B20: 7 | C20: =MID($B$5,VLOOKUP($B20,IP,C$13+1,FALSE),1) -> 0 | D20: =MID($B$5,VLOOKUP($B20,IP,D$13+1,FALSE),1) -> 0 | E20: =MID($B$5,VLOOKUP($B20,IP,E$13+1,FALSE),1) -> 0 | F20: =MID($B$5,VLOOKUP($B20,IP,F$13+1,FALSE),1) -> 1 | G20: =MID($B$5,VLOOKUP($B20,IP,G$13+1,FALSE),1) -> 1 | H20: =MID($B$5,VLOOKUP($B20,IP,H$13+1,FALSE),1) -> 0 | I20: =MID($B$5,VLOOKUP($B20,IP,I$13+1,FALSE),1) -> 0 | J20: =MID($B$5,VLOOKUP($B20,IP,J$13+1,FALSE),1) -> 0 | K20: =CONCATENATE(C20,D20,E20,F20,G20,H20,I20,J20) -> 00011000
B21: 8 | C21: =MID($B$5,VLOOKUP($B21,IP,C$13+1,FALSE),1) -> 1 | D21: =MID($B$5,VLOOKUP($B21,IP,D$13+1,FALSE),1) -> 0 | E21: =MID($B$5,VLOOKUP($B21,IP,E$13+1,FALSE),1) -> 1 | F21: =MID($B$5,VLOOKUP($B21,IP,F$13+1,FALSE),1) -> 0 | G21: =MID($B$5,VLOOKUP($B21,IP,G$13+1,FALSE),1) -> 1 | H21: =MID($B$5,VLOOKUP($B21,IP,H$13+1,FALSE),1) -> 1 | I21: =MID($B$5,VLOOKUP($B21,IP,I$13+1,FALSE),1) -> 0 | J21: =MID($B$5,VLOOKUP($B21,IP,J$13+1,FALSE),1) -> 1 | K21: =CONCATENATE(C21,D21,E21,F21,G21,H21,I21,J21) -> 10101101
K22: 1 | L22: =K22+4 -> 5 | M22: =L22+4 -> 9 | N22: =M22+4 -> 13 | O22: =N22+4 -> 17 | P22: =O22+4 -> 21 | Q22: =P22+4 -> 25 | R22: =Q22+4 -> 29
A23: L0 | B23: =CONCATENATE(K14,K15,K16,K17) -> 00010100101001111101011001111000 | K23: =MID($B23,K$22,4) -> 0001 | L23: =MID($B23,L$22,4) -> 0100 | M23: =MID($B23,M$22,4) -> 1010 | N23: =MID($B23,N$22,4) -> 0111 | O23: =MID($B23,O$22,4) -> 1101 | P23: =MID($B23,P$22,4) -> 0110 | Q23: =MID($B23,Q$22,4) -> 0111 | R23: =MID($B23,R$22,4) -> 1000 | S23: =BIN2HEX(K23) -> 1 | T23: =BIN2HEX(L23) -> 4 | U23: =BIN2HEX(M23) -> A | V23: =BIN2HEX(N23) -> 7 | W23: =BIN2HEX(O23) -> D | X23: =BIN2HEX(P23) -> 6 | Y23: =BIN2HEX(Q23) -> 7 | Z23: =BIN2HEX(R23) -> 8
A24: R0 | B24: =CONCATENATE(K18,K19,K20,K21) -> 00011000110010100001100010101101 | K24: =MID($B24,K$22,4) -> 0001 | L24: =MID($B24,L$22,4) -> 1000 | M24: =MID($B24,M$22,4) -> 1100 | N24: =MID($B24,N$22,4) -> 1010 | O24: =MID($B24,O$22,4) -> 0001 | P24: =MID($B24,P$22,4) -> 1000 | Q24: =MID($B24,Q$22,4) -> 1010 | R24: =MID($B24,R$22,4) -> 1101 | S24: =BIN2HEX(K24) -> 1 | T24: =BIN2HEX(L24) -> 8 | U24: =BIN2HEX(M24) -> C | V24: =BIN2HEX(N24) -> A | W24: =BIN2HEX(O24) -> 1 | X24: =BIN2HEX(P24) -> 8 | Y24: =BIN2HEX(Q24) -> A | Z24: =BIN2HEX(R24) -> D
B27: L0 | C27: =B23 -> 00010100101001111101011001111000 | K27: R0 | L27: =B24 -> 00011000110010100001100010101101 | U27: 0 | V27: =CONCATENATE(K27,"||",B27) -> R0||L0 | X27: =CONCATENATE(L27,C27) -> 0001100011001010000110001010110100010100101001111101011001111000
B28: L1 | C28: =L27 -> 00011000110010100001100010101101 | K28: R1 | L28: ='R1'!$B$49 -> 01011010011110001110001110010100 | U28: 1 | V28: =CONCATENATE(K28,"||",B28) -> R1||L1 | X28: =CONCATENATE(L28,C28) -> 0101101001111000111000111001010000011000110010100001100010101101
B29: L2 | C29: =L28 -> 01011010011110001110001110010100 | K29: R2 | L29: ='R2'!$B$49 -> 01001010000100100001000011110110 | U29: 2 | V29: =CONCATENATE(K29,"||",B29) -> R2||L2 | X29: =CONCATENATE(L29,C29) -> 0100101000010010000100001111011001011010011110001110001110010100
B30: L3 | C30: =L29 -> 01001010000100100001000011110110 | K30: R3 | L30: ='R3'!$B$49 -> 10111000000010001001010110010001 | U30: 3 | V30: =CONCATENATE(K30,"||",B30) -> R3||L3 | X30: =CONCATENATE(L30,C30) -> 1011100000001000100101011001000101001010000100100001000011110110
B31: L4 | C31: =L30 -> 10111000000010001001010110010001 | K31: R4 | L31: ='R4'!$B$49 -> 00100011011001110111100111000010 | U31: 4 | V31: =CONCATENATE(K31,"||",B31) -> R4||L4 | X31: =CONCATENATE(L31,C31) -> 0010001101100111011110011100001010111000000010001001010110010001
B32: L5 | C32: =L31 -> 00100011011001110111100111000010 | K32: R5 | L32: ='R5'!$B$49 -> 10100001010110100100101110000111 | U32: 5 | V32: =CONCATENATE(K32,"||",B32) -> R5||L5 | X32: =CONCATENATE(L32,C32) -> 1010000101011010010010111000011100100011011001110111100111000010
B33: L6 | C33: =L32 -> 10100001010110100100101110000111 | K33: R6 | L33: ='R6'!$B$49 -> 00101110100011111001110001100101 | U33: 6 | V33: =CONCATENATE(K33,"||",B33) -> R6||L6 | X33: =CONCATENATE(L33,C33) -> 0010111010001111100111000110010110100001010110100100101110000111
B34: L7 | C34: =L33 -> 00101110100011111001110001100101 | K34: R7 | L34: ='R7'!$B$49 -> 10101001111111000010000010100011 | U34: 7 | V34: =CONCATENATE(K34,"||",B34) -> R7||L7 | X34: =CONCATENATE(L34,C34) -> 1010100111111100001000001010001100101110100011111001110001100101
B35: L8 | C35: =L34 -> 10101001111111000010000010100011 | K35: R8 | L35: ='R8'!$B$49 -> 00110000100010111110111010010111 | U35: 8 | V35: =CONCATENATE(K35,"||",B35) -> R8||L8 | X35: =CONCATENATE(L35,C35) -> 0011000010001011111011101001011110101001111111000010000010100011
B36: L9 | C36: =L35 -> 00110000100010111110111010010111 | K36: R9 | L36: ='R9'!$B$49 -> 00010000101011111001110100110111 | U36: 9 | V36: =CONCATENATE(K36,"||",B36) -> R9||L9 | X36: =CONCATENATE(L36,C36) -> 0001000010101111100111010011011100110000100010111110111010010111
B37: L10 | C37: =L36 -> 00010000101011111001110100110111 | K37: R10 | L37: ='R10'!$B$49 -> 01101100101001101100101100100000 | U37: 10 | V37: =CONCATENATE(K37,"||",B37) -> R10||L10 | X37: =CONCATENATE(L37,C37) -> 0110110010100110110010110010000000010000101011111001110100110111
B38: L11 | C38: =L37 -> 01101100101001101100101100100000 | K38: R11 | L38: ='R11'!$B$49 -> 11111111001111000100100001011111 | U38: 11 | V38: =CONCATENATE(K38,"||",B38) -> R11||L11 | X38: =CONCATENATE(L38,C38) -> 1111111100111100010010000101111101101100101001101100101100100000
B39: L12 | C39: =L38 -> 11111111001111000100100001011111 | K39: R12 | L39: ='R12'!$B$49 -> 00100010101001011001011000111011 | U39: 12 | V39: =CONCATENATE(K39,"||",B39) -> R12||L12 | X39: =CONCATENATE(L39,C39) -> 0010001010100101100101100011101111111111001111000100100001011111
B40: L13 | C40: =L39 -> 00100010101001011001011000111011 | K40: R13 | L40: ='R13'!$B$49 -> 00111000011111001100110110101010 | U40: 13 | V40: =CONCATENATE(K40,"||",B40) -> R13||L13 | X40: =CONCATENATE(L40,C40) -> 0011100001111100110011011010101000100010101001011001011000111011
B41: L14 | C41: =L40 -> 00111000011111001100110110101010 | K41: R14 | L41: ='R14'!$B$49 -> 10111101001011011101001010101011 | U41: 14 | V41: =CONCATENATE(K41,"||",B41) -> R14||L14 | X41: =CONCATENATE(L41,C41) -> 1011110100101101110100101010101100111000011111001100110110101010
B42: L15 | C42: =L41 -> 10111101001011011101001010101011 | K42: R15 | L42: ='R15'!$B$49 -> 11001111001001101011010001110010 | U42: 15 | V42: =CONCATENATE(K42,"||",B42) -> R15||L15 | X42: =CONCATENATE(L42,C42) -> 1100111100100110101101000111001010111101001011011101001010101011
B43: L16 | C43: =L42 -> 11001111001001101011010001110010 | K43: R16 | L43: ='R16'!$B$49 -> 00011001101110101001001000010010 | U43: 16 | V43: =CONCATENATE(K43,"||",B43) -> R16||L16 | X43: =CONCATENATE(L43,C43) -> 0001100110111010100100100001001011001111001001101011010001110010
C45: 1 | D45: =C45+4 -> 5 | E45: =D45+4 -> 9 | F45: =E45+4 -> 13 | G45: =F45+4 -> 17 | H45: =G45+4 -> 21 | I45: =H45+4 -> 25 | J45: =I45+4 -> 29 | L45: 1 | M45: =L45+4 -> 5 | N45: =M45+4 -> 9 | O45: =N45+4 -> 13 | P45: =O45+4 -> 17 | Q45: =P45+4 -> 21 | R45: =Q45+4 -> 25 | S45: =R45+4 -> 29
...

Sheet AVALANCHE EFFECT
B1: 1 | C1: 2 | D1: 3 | E1: 4 | F1: 5 | G1: 6 | H1: 7 | I1: 8 | J1: 9 | K1: 10 | L1: 11 | M1: 12 | N1: 13 | O1: 14 | P1: 15 | Q1: 16 | R1: 17 | S1: 18 | T1: 19 | U1: 20 | V1: 21 | W1: 22 | X1: 23 | Y1: 24 | Z1: 25 | AA1: 26 | AB1: 27 | AC1: 28 | AD1: 29 | AE1: 30 | AF1: 31 | AG1: 32 | AH1: 33 | AI1: 34 | AJ1: 35 | AK1: 36 | AL1: 37 | AM1: 38 | AN1: 39 | AO1: 40 | AP1: 41 | AQ1: 42 | AR1: 43 | AS1: 44 | AT1: 45 | AU1: 46 | AV1: 47 | AW1: 48 | AX1: 49 | AY1: 50 | AZ1: 51 | BA1: 52 | BB1: 53 | BC1: 54 | BD1: 55 | BE1: 56 | BF1: 57 | BG1: 58 | BH1: 59 | BI1: 60 | BJ1: 61 | BK1: 62 | BL1: 63 | BM1: 64 | BO1: 1 | BP1: 2 | BQ1: 3 | BR1: 4 | BS1: 5 | BT1: 6 | BU1: 7 | BV1: 8 | BW1: 9 | BX1: 10 | BY1: 11 | BZ1: 12 | CA1: 13 | CB1: 14 | CC1: 15 | CD1: 16 | CE1: 17 | CF1: 18 | CG1: 19 | CH1: 20 | CI1: 21 | CJ1: 22 | CK1: 23 | CL1: 24 | CM1: 25 | CN1: 26 | CO1: 27 | CP1: 28 | CQ1: 29 | CR1: 30 | CS1: 31 | CT1: 32 | CU1: 33 | CV1: 34 | CW1: 35 | CX1: 36 | CY1: 37 | CZ1: 38 | DA1: 39 | DB1: 40 | DC1: 41 | DD1: 42 | DE1: 43 | DF1: 44 | DG1: 45 | DH1: 46 | DI1: 47 | DJ1: 48 | DK1: 49 | DL1: 50 | DM1: 51 | DN1: 52 | DO1: 53 | DP1: 54 | DQ1: 55 | DR1: 56 | DS1: 57 | DT1: 58 | DU1: 59 | DV1: 60 | DW1: 61 | DX1: 62 | DY1: 63 | DZ1: 64 | EB1: 1 | EC1: 2 | ED1: 3 | EE1: 4 | EF1: 5 | EG1: 6 | EH1: 7 | EI1: 8 | EJ1: 9 | EK1: 10 | EL1: 11 | EM1: 12 | EN1: 13 | EO1: 14 | EP1: 15 | EQ1: 16 | ER1: 17 | ES1: 18 | ET1: 19 | EU1: 20 | EV1: 21 | EW1: 22 | EX1: 23 | EY1: 24 | EZ1: 25 | FA1: 26 | FB1: 27 | FC1: 28 | FD1: 29 | FE1: 30 | FF1: 31 | FG1: 32 | FH1: 33 | FI1: 34 | FJ1: 35 | FK1: 36 | FL1: 37 | FM1: 38 | FN1: 39 | FO1: 40 | FP1: 41 | FQ1: 42 | FR1: 43 | FS1: 44 | FT1: 45 | FU1: 46 | FV1: 47 | FW1: 48 | FX1: 49 | FY1: 50 | FZ1: 51 | GA1: 52 | GB1: 53 | GC1: 54 | GD1: 55 | GE1: 56 | GF1: 57 | GG1: 58 | GH1: 59 | GI1: 60 | GJ1: 61 | GK1: 62 | GL1: 63 | GM1: 64 | GO1: NUMBER OF BITS
A2: ROUND | B2: MESSAGE 1 | BO2: MESSAGE 2 | EB2: DIFFERENCE BIT BY BIT | GO2: THAT ARE DIFF | GU2: MESSAGE 1 | GW2: MESSAGE 2
A3: 0 | B3: =VLOOKUP(A3,MESSAGE,2,FALSE) -> 0000000100000000000000000000000000000000000000000000000000000000 | BO3: =VLOOKUP(A3,MESSAGE, 4,FALSE) -> 0000000100000000000000000000000000000000000000010000000000000000 | GT3: 0 | GU3: 0000000100000000000000000000000000000000000000000000000000000000 | GW3: 0000000100000000000000000000000000000000000000010000000000000000
B4: =MID($B3,B$1,1) -> 0 | C4: =MID($B3,C$1,1) -> 0 | D4: =MID($B3,D$1,1) -> 0 | E4: =MID($B3,E$1,1) -> 0 | F4: =MID($B3,F$1,1) -> 0 | G4: =MID($B3,G$1,1) -> 0 | H4: =MID($B3,H$1,1) -> 0 | I4: =MID($B3,I$1,1) -> 1 | ... BM4: =MID($B3,BM$1,1) -> 0 | BO4: =MID($BO3,BO$1,1) -> 0 | BP4: =MID($BO3,BP$1,1) -> 0 | BQ4: =MID($BO3,BQ$1,1) -> 0 | BR4: =MID($BO3,BR$1,1) -> 0 | BS4: =MID($BO3,BS$1,1) -> 0 | BT4: =MID($BO3,BT$1,1) -> 0 | BU4: =MID($BO3,BU$1,1) -> 0 | BV4: =MID($BO3,BV$1,1) -> 1 | ... DZ4: =MID($BO3,DZ$1,1) -> 0 | EB4: =IF(B4=BO4,0,1) -> 0 | EC4: =IF(C4=BP4,0,1) -> 0 | ED4: =IF(D4=BQ4,0,1) -> 0 | EE4: =IF(E4=BR4,0,1) -> 0 | EF4: =IF(F4=BS4,0,1) -> 0 | EG4: =IF(G4=BT4,0,1) -> 0 | EH4: =IF(H4=BU4,0,1) -> 0 | EI4: =IF(I4=BV4,0,1) -> 0 | ... GM4: =IF(BM4=DZ4,0,1) -> 0 | GO4: =SUM(EB4:GM4) -> 1 | GT4: 1 | GU4: 1011011110100101010001111110101000000001000000000000000000000000 | GW4: 1011011110100100010001111110101000000001000000000000000000000000
A5: 1 | B5: =VLOOKUP(A5,MESSAGE,2,FALSE) -> 1011011110100101010001111110101000000001000000000000000000000000 | BO5: =VLOOKUP(A5,MESSAGE, 4,FALSE) -> 1011011110100100010001111110101000000001000000000000000000000000 | GT5: 2 | GU5: 0101010101111101101000001001110010110111101001010100011111101010 | GW5: 1111010100111101101100000001110010110111101001000100011111101010
B6: =MID($B5,B$1,1) -> 1 | C6: =MID($B5,C$1,1) -> 0 | D6: =MID($B5,D$1,1) -> 1 | E6: =MID($B5,E$1,1) -> 1 | F6: =MID($B5,F$1,1) -> 0 | G6: =MID($B5,G$1,1) -> 1 | H6: =MID($B5,H$1,1) -> 1 | I6: =MID($B5,I$1,1) -> 1 | ... BM6: =MID($B5,BM$1,1) -> 0 | BO6: =MID($BO5,BO$1,1) -> 1 | BP6: =MID($BO5,BP$1,1) -> 0 | BQ6: =MID($BO5,BQ$1,1) -> 1 | BR6: =MID($BO5,BR$1,1) -> 1 | BS6: =MID($BO5,BS$1,1) -> 0 | BT6: =MID($BO5,BT$1,1) -> 1 | BU6: =MID($BO5,BU$1,1) -> 1 | BV6: =MID($BO5,BV$1,1) -> 1 | ... DZ6: =MID($BO5,DZ$1,1) -> 0 | EB6: =IF(B6=BO6,0,1) -> 0 | EC6: =IF(C6=BP6,0,1) -> 0 | ED6: =IF(D6=BQ6,0,1) -> 0 | EE6: =IF(E6=BR6,0,1) -> 0 | EF6: =IF(F6=BS6,0,1) -> 0 | EG6: =IF(G6=BT6,0,1) -> 0 | EH6: =IF(H6=BU6,0,1) -> 0 | EI6: =IF(I6=BV6,0,1) -> 0 | ... GM6: =IF(BM6=DZ6,0,1) -> 0 | GO6: =SUM(EB6:GM6) -> 1 | GT6: 3 | GU6: 1111111000010011100111111111110001010101011111011010000010011100 | GW6: 1111110100100111001100100101010011110101001111011011000000011100
A7: 2 | B7: =VLOOKUP(A7,MESSAGE,2,FALSE) -> 0101010101111101101000001001110010110111101001010100011111101010 | BO7: =VLOOKUP(A7,MESSAGE, 4,FALSE) -> 1111010100111101101100000001110010110111101001000100011111101010 | GT7: 4 | GU7: 1100111000110111100001110001010111111110000100111001111111111100 | GW7: 1101100100011000110111100011010111111101001001110011001001010100
B8: =MID($B7,B$1,1) -> 0 | C8: =MID($B7,C$1,1) -> 1 | D8: =MID($B7,D$1,1) -> 0 | E8: =MID($B7,E$1,1) -> 1 | F8: =MID($B7,F$1,1) -> 0 | G8: =MID($B7,G$1,1) -> 1 | H8: =MID($B7,H$1,1) -> 0 | I8: =MID($B7,I$1,1) -> 1 | ... BM8: =MID($B7,BM$1,1) -> 0 | BO8: =MID($BO7,BO$1,1) -> 1 | BP8: =MID($BO7,BP$1,1) -> 1 | BQ8: =MID($BO7,BQ$1,1) -> 1 | BR8: =MID($BO7,BR$1,1) -> 1 | BS8: =MID($BO7,BS$1,1) -> 0 | BT8: =MID($BO7,BT$1,1) -> 1 | BU8: =MID($BO7,BU$1,1) -> 0 | BV8: =MID($BO7,BV$1,1) -> 1 | ... DZ8: =MID($BO7,DZ$1,1) -> 0 | EB8: =IF(B8=BO8,0,1) -> 1 | EC8: =IF(C8=BP8,0,1) -> 0 | ED8: =IF(D8=BQ8,0,1) -> 1 | EE8: =IF(E8=BR8,0,1) -> 0 | EF8: =IF(F8=BS8,0,1) -> 0 | EG8: =IF(G8=BT8,0,1) -> 0 | EH8: =IF(H8=BU8,0,1) -> 0 | EI8: =IF(I8=BV8,0,1) -> 0 | ... GM8: =IF(BM8=DZ8,0,1) -> 0 | GO8: =SUM(EB8:GM8) -> 6 | GT8: 5 | GU8: 1100001010000101011111101111110111001110001101111000011100010101 | GW8: 0110001010010101110000000100011011011001000110001101111000110101
A9: 3 | B9: =VLOOKUP(A9,MESSAGE,2,FALSE) -> 1111111000010011100111111111110001010101011111011010000010011100 | BO9: =VLOOKUP(A9,MESSAGE, 4,FALSE) -> 1111110100100111001100100101010011110101001111011011000000011100 | GT9: 6 | GU9: 0001111000111001010010010101100111000010100001010111111011111101 | GW9: 0000101101000000000100110101010101100010100101011100000001000110
B10: =MID($B9,B$1,1) -> 1 | C10: =MID($B9,C$1,1) -> 1 | D10: =MID($B9,D$1,1) -> 1 | E10: =MID($B9,E$1,1) -> 1 | F10: =MID($B9,F$1,1) -> 1 | G10: =MID($B9,G$1,1) -> 1 | H10: =MID($B9,H$1,1) -> 1 | I10: =MID($B9,I$1,1) -> 0 | ... BM10: =MID($B9,BM$1,1) -> 0 | BO10: =MID($BO9,BO$1,1) -> 1 | BP10: =MID($BO9,BP$1,1) -> 1 | BQ10: =MID($BO9,BQ$1,1) -> 1 | BR10: =MID($BO9,BR$1,1) -> 1 | BS10: =MID($BO9,BS$1,1) -> 1 | BT10: =MID($BO9,BT$1,1) -> 1 | BU10: =MID($BO9,BU$1,1) -> 0 | BV10: =MID($BO9,BV$1,1) -> 1 | ... DZ10: =MID($BO9,DZ$1,1) -> 0 | EB10: =IF(B10=BO10,0,1) -> 0 | EC10: =IF(C10=BP10,0,1) -> 0 | ED10: =IF(D10=BQ10,0,1) -> 0 | EE10: =IF(E10=BR10,0,1) -> 0 | EF10: =IF(F10=BS10,0,1) -> 0 | EG10: =IF(G10=BT10,0,1) -> 0 | EH10: =IF(H10=BU10,0,1) -> 1 | EI10: =IF(I10=BV10,0,1) -> 1 | ... GM10: =IF(BM10=DZ10,0,1) -> 0 | GO10: =SUM(EB10:GM10) -> 18 | GT10: 7 | GU10: 0111100011111100001000000101100100011110001110010100100101011001 | GW10: 1000001100100100001010100111101100001011010000000001001101010101
A11: 4 | B11: =VLOOKUP(A11,MESSAGE,2,FALSE) -> 1100111000110111100001110001010111111110000100111001111111111100 | BO11: =VLOOKUP(A11,MESSAGE, 4,FALSE) -> 1101100100011000110111100011010111111101001001110011001001010100 | GT11: 8 | GU11: 1000100000011110100011000000010001111000111111000010000001011001 | GW11: 0110001101100011010100011000101010000011001001000010101001111011
B12: =MID($B11,B$1,1) -> 1 | C12: =MID($B11,C$1,1) -> 1 | D12: =MID($B11,D$1,1) -> 0 | E12: =MID($B11,E$1,1) -> 0 | F12: =MID($B11,F$1,1) -> 1 | G12: =MID($B11,G$1,1) -> 1 | H12: =MID($B11,H$1,1) -> 1 | I12: =MID($B11,I$1,1) -> 0 | ... BM12: =MID($B11,BM$1,1) -> 0 | BO12: =MID($BO11,BO$1,1) -> 1 | BP12: =MID($BO11,BP$1,1) -> 1 | BQ12: =MID($BO11,BQ$1,1) -> 0 | BR12: =MID($BO11,BR$1,1) -> 1 | BS12: =MID($BO11,BS$1,1) -> 1 | BT12: =MID($BO11,BT$1,1) -> 0 | BU12: =MID($BO11,BU$1,1) -> 0 | BV12: =MID($BO11,BV$1,1) -> 1 | ... DZ12: =MID($BO11,DZ$1,1) -> 0 | EB12: =IF(B12=BO12,0,1) -> 0 | EC12: =IF(C12=BP12,0,1) -> 0 | ED12: =IF(D12=BQ12,0,1) -> 0 | EE12: =IF(E12=BR12,0,1) -> 1 | EF12: =IF(F12=BS12,0,1) -> 0 | EG12: =IF(G12=BT12,0,1) -> 1 | EH12: =IF(H12=BU12,0,1) -> 1 | EI12: =IF(I12=BV12,0,1) -> 1 | ... GM12: =IF(BM12=DZ12,0,1) -> 0 | GO12: =SUM(EB12:GM12) -> 27 | GT12: 9 | GU12: 0010000000110101000111010000101110001000000111101000110000000100 | GW12: 1101101111011001110100111010100001100011011000110101000110001010
A13: 5 | B13: =VLOOKUP(A13,MESSAGE,2,FALSE) -> 1100001010000101011111101111110111001110001101111000011100010101 | BO13: =VLOOKUP(A13,MESSAGE, 4,FALSE) -> 0110001010010101110000000100011011011001000110001101111000110101 | GT13: 10 | GU13: 1110010101000011100000001001100000100000001101010001110100001011 | GW13: 1001010001001000001100010110111111011011110110011101001110101000
B14: =MID($B13,B$1,1) -> 1 | C14: =MID($B13,C$1,1) -> 1 | D14: =MID($B13,D$1,1) -> 0 | E14: =MID($B13,E$1,1) -> 0 | F14: =MID($B13,F$1,1) -> 0 | G14: =MID($B13,G$1,1) -> 0 | H14: =MID($B13,H$1,1) -> 1 | I14: =MID($B13,I$1,1) -> 0 | ... BM14: =MID($B13,BM$1,1) -> 1 | BO14: =MID($BO13,BO$1,1) -> 0 | BP14: =MID($BO13,BP$1,1) -> 1 | BQ14: =MID($BO13,BQ$1,1) -> 1 | BR14: =MID($BO13,BR$1,1) -> 0 | BS14: =MID($BO13,BS$1,1) -> 0 | BT14: =MID($BO13,BT$1,1) -> 0 | BU14: =MID($BO13,BU$1,1) -> 1 | BV14: =MID($BO13,BV$1,1) -> 0 | ... DZ14: =MID($BO13,DZ$1,1) -> 1 | EB14: =IF(B14=BO14,0,1) -> 1 | EC14: =IF(C14=BP14,0,1) -> 0 | ED14: =IF(D14=BQ14,0,1) -> 1 | EE14: =IF(E14=BR14,0,1) -> 0 | EF14: =IF(F14=BS14,0,1) -> 0 | EG14: =IF(G14=BT14,0,1) -> 0 | EH14: =IF(H14=BU14,0,1) -> 0 | EI14: =IF(I14=BV14,0,1) -> 0 | ... GM14: =IF(BM14=DZ14,0,1) -> 0 | GO14: =SUM(EB14:GM14) -> 29 | GT14: 11 | GU14: 1010100111001010110001001101111111100101010000111000000010011000 | GW14: 1110010110100110111011100011010110010100010010000011000101101111
A15: 6 | B15: =VLOOKUP(A15,MESSAGE,2,FALSE) -> 0001111000111001010010010101100111000010100001010111111011111101 | BO15: =VLOOKUP(A15,MESSAGE, 4,FALSE) -> 0000101101000000000100110101010101100010100101011100000001000110 | GT15: 12 | GU15: 1100110111111000000011111011000110101001110010101100010011011111 | GW15: 1011101101001010010001011101010011100101101001101110111000110101
B16: =MID($B15,B$1,1) -> 0 | C16: =MID($B15,C$1,1) -> 0 | D16: =MID($B15,D$1,1) -> 0 | E16: =MID($B15,E$1,1) -> 1 | F16: =MID($B15,F$1,1) -> 1 | G16: =MID($B15,G$1,1) -> 1 | H16: =MID($B15,H$1,1) -> 1 | I16: =MID($B15,I$1,1) -> 0 | ... BM16: =MID($B15,BM$1,1) -> 1 | BO16: =MID($BO15,BO$1,1) -> 0 | BP16: =MID($BO15,BP$1,1) -> 0 | BQ16: =MID($BO15,BQ$1,1) -> 0 | BR16: =MID($BO15,BR$1,1) -> 0 | BS16: =MID($BO15,BS$1,1) -> 1 | BT16: =MID($BO15,BT$1,1) -> 0 | BU16: =MID($BO15,BU$1,1) -> 1 | BV16: =MID($BO15,BV$1,1) -> 1 | ... DZ16: =MID($BO15,DZ$1,1) -> 0 | EB16: =IF(B16=BO16,0,1) -> 0 | EC16: =IF(C16=BP16,0,1) -> 0 | ED16: =IF(D16=BQ16,0,1) -> 0 | EE16: =IF(E16=BR16,0,1) -> 1 | EF16: =IF(F16=BS16,0,1) -> 0 | EG16: =IF(G16=BT16,0,1) -> 1 | EH16: =IF(H16=BU16,0,1) -> 0 | EI16: =IF(I16=BV16,0,1) -> 1 | ... GM16: =IF(BM16=DZ16,0,1) -> 1 | GO16: =SUM(EB16:GM16) -> 29 | GT16: 13 | GU16: 0010110000100011010010010111001011001101111110000000111110110001 | GW16: 0101111011000111110001001110111010111011010010100100010111010100
A17: 7 | B17: =VLOOKUP(A17,MESSAGE,2,FALSE) -> 0111100011111100001000000101100100011110001110010100100101011001 | BO17: =VLOOKUP(A17,MESSAGE, 4,FALSE) -> 1000001100100100001010100111101100001011010000000001001101010101 | GT17: 14 | GU17: 0100100111111001100001110110100100101100001000110100100101110010 | GW17: 0100011110000101011000101010111101011110110001111100010011101110
B18: =MID($B17,B$1,1) -> 0 | C18: =MID($B17,C$1,1) -> 1 | D18: =MID($B17,D$1,1) -> 1 | E18: =MID($B17,E$1,1) -> 1 | F18: =MID($B17,F$1,1) -> 1 | G18: =MID($B17,G$1,1) -> 0 | H18: =MID($B17,H$1,1) -> 0 | I18: =MID($B17,I$1,1) -> 0 | ... BM18: =MID($B17,BM$1,1) -> 1 | BO18: =MID($BO17,BO$1,1) -> 1 | BP18: =MID($BO17,BP$1,1) -> 0 | BQ18: =MID($BO17,BQ$1,1) -> 0 | BR18: =MID($BO17,BR$1,1) -> 0 | BS18: =MID($BO17,BS$1,1) -> 0 | BT18: =MID($BO17,BT$1,1) -> 0 | BU18: =MID($BO17,BU$1,1) -> 1 | BV18: =MID($BO17,BV$1,1) -> 1 | ... DZ18: =MID($BO17,DZ$1,1) -> 1 | EB18: =IF(B18=BO18,0,1) -> 1 | EC18: =IF(C18=BP18,0,1) -> 1 | ED18: =IF(D18=BQ18,0,1) -> 1 | EE18: =IF(E18=BR18,0,1) -> 1 | EF18: =IF(F18=BS18,0,1) -> 1 | EG18: =IF(G18=BT18,0,1) -> 0 | EH18: =IF(H18=BU18,0,1) -> 1 | EI18: =IF(I18=BV18,0,1) -> 1 | ... GM18: =IF(BM18=DZ18,0,1) -> 0 | GO18: =SUM(EB18:GM18) -> 29 | GT18: 15 | GU18: 0000110100111101011000100001101001001001111110011000011101101001 | GW18: 1110011001100000101100001100001101000111100001010110001010101111
A19: 8 | B19: =VLOOKUP(A19,MESSAGE,2,FALSE) -> 1000100000011110100011000000010001111000111111000010000001011001 | BO19: =VLOOKUP(A19,MESSAGE, 4,FALSE) -> 0110001101100011010100011000101010000011001001000010101001111011 | GT19: 16 | GU19: 1111110110100010001110011110001000001101001111010110001000011010 | GW19: 1101101011001110001100001010100011100110011000001011000011000011
B20: =MID($B19,B$1,1) -> 1 | C20: =MID($B19,C$1,1) -> 0 | D20: =MID($B19,D$1,1) -> 0 | E20: =MID($B19,E$1,1) -> 0 | F20: =MID($B19,F$1,1) -> 1 | G20: =MID($B19,G$1,1) -> 0 | H20: =MID($B19,H$1,1) -> 0 | I20: =MID($B19,I$1,1) -> 0 | ... BM20: =MID($B19,BM$1,1) -> 1 | BO20: =MID($BO19,BO$1,1) -> 0 | BP20: =MID($BO19,BP$1,1) -> 1 | BQ20: =MID($BO19,BQ$1,1) -> 1 | BR20: =MID($BO19,BR$1,1) -> 0 | BS20: =MID($BO19,BS$1,1) -> 0 | BT20: =MID($BO19,BT$1,1) -> 0 | BU20: =MID($BO19,BU$1,1) -> 1 | BV20: =MID($BO19,BV$1,1) -> 1 | ... DZ20: =MID($BO19,DZ$1,1) -> 1 | EB20: =IF(B20=BO20,0,1) -> 1 | EC20: =IF(C20=BP20,0,1) -> 1 | ED20: =IF(D20=BQ20,0,1) -> 1 | EE20: =IF(E20=BR20,0,1) -> 0 | EF20: =IF(F20=BS20,0,1) -> 1 | EG20: =IF(G20=BT20,0,1) -> 0 | EH20: =IF(H20=BU20,0,1) -> 1 | EI20: =IF(I20=BV20,0,1) -> 1 | ... GM20: =IF(BM20=DZ20,0,1) -> 0 | GO20: =SUM(EB20:GM20) -> 37
A21: 9 | B21: =VLOOKUP(A21,MESSAGE,2,FALSE) -> 0010000000110101000111010000101110001000000111101000110000000100 | BO21: =VLOOKUP(A21,MESSAGE, 4,FALSE) -> 1101101111011001110100111010100001100011011000110101000110001010
B22: =MID($B21,B$1,1) -> 0 | C22: =MID($B21,C$1,1) -> 0 | D22: =MID($B21,D$1,1) -> 1 | E22: =MID($B21,E$1,1) -> 0 | F22: =MID($B21,F$1,1) -> 0 | G22: =MID($B21,G$1,1) -> 0 | H22: =MID($B21,H$1,1) -> 0 | I22: =MID($B21,I$1,1) -> 0 | ... BM22: =MID($B21,BM$1,1) -> 0 | BO22: =MID($BO21,BO$1,1) -> 1 | BP22: =MID($BO21,BP$1,1) -> 1 | BQ22: =MID($BO21,BQ$1,1) -> 0 | BR22: =MID($BO21,BR$1,1) -> 1 | BS22: =MID($BO21,BS$1,1) -> 1 | BT22: =MID($BO21,BT$1,1) -> 0 | BU22: =MID($BO21,BU$1,1) -> 1 | BV22: =MID($BO21,BV$1,1) -> 1 | ... DZ22: =MID($BO21,DZ$1,1) -> 0 | EB22: =IF(B22=BO22,0,1) -> 1 | EC22: =IF(C22=BP22,0,1) -> 1 | ED22: =IF(D22=BQ22,0,1) -> 1 | EE22: =IF(E22=BR22,0,1) -> 1 | EF22: =IF(F22=BS22,0,1) -> 1 | EG22: =IF(G22=BT22,0,1) -> 0 | EH22: =IF(H22=BU22,0,1) -> 1 | EI22: =IF(I22=BV22,0,1) -> 1 | ... GM22: =IF(BM22=DZ22,0,1) -> 0 | GO22: =SUM(EB22:GM22) -> 43
A23: 10 | B23: =VLOOKUP(A23,MESSAGE,2,FALSE) -> 1110010101000011100000001001100000100000001101010001110100001011 | BO23: =VLOOKUP(A23,MESSAGE, 4,FALSE) -> 1001010001001000001100010110111111011011110110011101001110101000
B24: =MID($B23,B$1,1) -> 1 | C24: =MID($B23,C$1,1) -> 1 | D24: =MID($B23,D$1,1) -> 1 | E24: =MID($B23,E$1,1) -> 0 | F24: =MID($B23,F$1,1) -> 0 | G24: =MID($B23,G$1,1) -> 1 | H24: =MID($B23,H$1,1) -> 0 | I24: =MID($B23,I$1,1) -> 1 | ... BM24: =MID($B23,BM$1,1) -> 1 | BO24: =MID($BO23,BO$1,1) -> 1 | BP24: =MID($BO23,BP$1,1) -> 0 | BQ24: =MID($BO23,BQ$1,1) -> 0 | BR24: =MID($BO23,BR$1,1) -> 1 | BS24: =MID($BO23,BS$1,1) -> 0 | BT24: =MID($BO23,BT$1,1) -> 1 | BU24: =MID($BO23,BU$1,1) -> 0 | BV24: =MID($BO23,BV$1,1) -> 0 | ... DZ24: =MID($BO23,DZ$1,1) -> 0 | EB24: =IF(B24=BO24,0,1) -> 0 | EC24: =IF(C24=BP24,0,1) -> 1 | ED24: =IF(D24=BQ24,0,1) -> 1 | EE24: =IF(E24=BR24,0,1) -> 1 | EF24: =IF(F24=BS24,0,1) -> 0 | EG24: =IF(G24=BT24,0,1) -> 0 | EH24: =IF(H24=BU24,0,1) -> 0 | EI24: =IF(I24=BV24,0,1) -> 1 | ... GM24: =IF(BM24=DZ24,0,1) -> 1 | GO24: =SUM(EB24:GM24) -> 39
A25: 11 | B25: =VLOOKUP(A25,MESSAGE,2,FALSE) -> 1010100111001010110001001101111111100101010000111000000010011000 | BO25: =VLOOKUP(A25,MESSAGE, 4,FALSE) -> 1110010110100110111011100011010110010100010010000011000101101111
B26: =MID($B25,B$1,1) -> 1 | C26: =MID($B25,C$1,1) -> 0 | D26: =MID($B25,D$1,1) -> 1 | E26: =MID($B25,E$1,1) -> 0 | F26: =MID($B25,F$1,1) -> 1 | G26: =MID($B25,G$1,1) -> 0 | H26: =MID($B25,H$1,1) -> 0 | I26: =MID($B25,I$1,1) -> 1 | ... BM26: =MID($B25,BM$1,1) -> 0 | BO26: =MID($BO25,BO$1,1) -> 1 | BP26: =MID($BO25,BP$1,1) -> 1 | BQ26: =MID($BO25,BQ$1,1) -> 1 | BR26: =MID($BO25,BR$1,1) -> 0 | BS26: =MID($BO25,BS$1,1) -> 0 | BT26: =MID($BO25,BT$1,1) -> 1 | BU26: =MID($BO25,BU$1,1) -> 0 | BV26: =MID($BO25,BV$1,1) -> 1 | ... DZ26: =MID($BO25,DZ$1,1) -> 1 | EB26: =IF(B26=BO26,0,1) -> 0 | EC26: =IF(C26=BP26,0,1) -> 1 | ED26: =IF(D26=BQ26,0,1) -> 0 | EE26: =IF(E26=BR26,0,1) -> 0 | EF26: =IF(F26=BS26,0,1) -> 1 | EG26: =IF(G26=BT26,0,1) -> 1 | EH26: =IF(H26=BU26,0,1) -> 0 | EI26: =IF(I26=BV26,0,1) -> 0 | ... GM26: =IF(BM26=DZ26,0,1) -> 1 | GO26: =SUM(EB26:GM26) -> 33
A27: 12 | B27: =VLOOKUP(A27,MESSAGE,2,FALSE) -> 1100110111111000000011111011000110101001110010101100010011011111 | BO27: =VLOOKUP(A27,MESSAGE, 4,FALSE) -> 1011101101001010010001011101010011100101101001101110111000110101
B28: =MID($B27,B$1,1) -> 1 | C28: =MID($B27,C$1,1) -> 1 | D28: =MID($B27,D$1,1) -> 0 | E28: =MID($B27,E$1,1) -> 0 | F28: =MID($B27,F$1,1) -> 1 | G28: =MID($B27,G$1,1) -> 1 | H28: =MID($B27,H$1,1) -> 0 | I28: =MID($B27,I$1,1) -> 1 | ... BM28: =MID($B27,BM$1,1) -> 1 | BO28: =MID($BO27,BO$1,1) -> 1 | BP28: =MID($BO27,BP$1,1) -> 0 | BQ28: =MID($BO27,BQ$1,1) -> 1 | BR28: =MID($BO27,BR$1,1) -> 1 | BS28: =MID($BO27,BS$1,1) -> 1 | BT28: =MID($BO27,BT$1,1) -> 0 | BU28: =MID($BO27,BU$1,1) -> 1 | BV28: =MID($BO27,BV$1,1) -> 1 | ... DZ28: =MID($BO27,DZ$1,1) -> 1 | EB28: =IF(B28=BO28,0,1) -> 0 | EC28: =IF(C28=BP28,0,1) -> 1 | ED28: =IF(D28=BQ28,0,1) -> 1 | EE28: =IF(E28=BR28,0,1) -> 1 | EF28: =IF(F28=BS28,0,1) -> 0 | EG28: =IF(G28=BT28,0,1) -> 1 | EH28: =IF(H28=BU28,0,1) -> 1 | EI28: =IF(I28=BV28,0,1) -> 0 | ... GM28: =IF(BM28=DZ28,0,1) -> 0 | GO28: =SUM(EB28:GM28) -> 31
A29: 13 | B29: =VLOOKUP(A29,MESSAGE,2,FALSE) -> 0010110000100011010010010111001011001101111110000000111110110001 | BO29: =VLOOKUP(A29,MESSAGE, 4,FALSE) -> 0101111011000111110001001110111010111011010010100100010111010100
B30: =MID($B29,B$1,1) -> 0 | C30: =MID($B29,C$1,1) -> 0 | D30: =MID($B29,D$1,1) -> 1 | E30: =MID($B29,E$1,1) -> 0 | F30: =MID($B29,F$1,1) -> 1 | G30: =MID($B29,G$1,1) -> 1 | H30: =MID($B29,H$1,1) -> 0 | I30: =MID($B29,I$1,1) -> 0 | ... BM30: =MID($B29,BM$1,1) -> 1 | BO30: =MID($BO29,BO$1,1) -> 0 | BP30: =MID($BO29,BP$1,1) -> 1 | BQ30: =MID($BO29,BQ$1,1) -> 0 | BR30: =MID($BO29,BR$1,1) -> 1 | BS30: =MID($BO29,BS$1,1) -> 1 | BT30: =MID($BO29,BT$1,1) -> 1 | BU30: =MID($BO29,BU$1,1) -> 1 | BV30: =MID($BO29,BV$1,1) -> 0 | ... DZ30: =MID($BO29,DZ$1,1) -> 0 | EB30: =IF(B30=BO30,0,1) -> 0 | EC30: =IF(C30=BP30,0,1) -> 1 | ED30: =IF(D30=BQ30,0,1) -> 1 | EE30: =IF(E30=BR30,0,1) -> 1 | EF30: =IF(F30=BS30,0,1) -> 0 | EG30: =IF(G30=BT30,0,1) -> 0 | EH30: =IF(H30=BU30,0,1) -> 1 | EI30: =IF(I30=BV30,0,1) -> 0 | ... GM30: =IF(BM30=DZ30,0,1) -> 1 | GO30: =SUM(EB30:GM30) -> 32
A31: 14 | B31: =VLOOKUP(A31,MESSAGE,2,FALSE) -> 0100100111111001100001110110100100101100001000110100100101110010 | BO31: =VLOOKUP(A31,MESSAGE, 4,FALSE) -> 0100011110000101011000101010111101011110110001111100010011101110
B32: =MID($B31,B$1,1) -> 0 | C32: =MID($B31,C$1,1) -> 1 | D32: =MID($B31,D$1,1) -> 0 | E32: =MID($B31,E$1,1) -> 0 | F32: =MID($B31,F$1,1) -> 1 | G32: =MID($B31,G$1,1) -> 0 | H32: =MID($B31,H$1,1) -> 0 | I32: =MID($B31,I$1,1) -> 1 | ... BM32: =MID($B31,BM$1,1) -> 0 | BO32: =MID($BO31,BO$1,1) -> 0 | BP32: =MID($BO31,BP$1,1) -> 1 | BQ32: =MID($BO31,BQ$1,1) -> 0 | BR32: =MID($BO31,BR$1,1) -> 0 | BS32: =MID($BO31,BS$1,1) -> 0 | BT32: =MID($BO31,BT$1,1) -> 1 | BU32: =MID($BO31,BU$1,1) -> 1 | BV32: =MID($BO31,BV$1,1) -> 1 | ... DZ32: =MID($BO31,DZ$1,1) -> 0 | EB32: =IF(B32=BO32,0,1) -> 0 | EC32: =IF(C32=BP32,0,1) -> 0 | ED32: =IF(D32=BQ32,0,1) -> 0 | EE32: =IF(E32=BR32,0,1) -> 0 | EF32: =IF(F32=BS32,0,1) -> 1 | EG32: =IF(G32=BT32,0,1) -> 1 | EH32: =IF(H32=BU32,0,1) -> 1 | EI32: =IF(I32=BV32,0,1) -> 0 | ... GM32: =IF(BM32=DZ32,0,1) -> 0 | GO32: =SUM(EB32:GM32) -> 33
A33: 15 | B33: =VLOOKUP(A33,MESSAGE,2,FALSE) -> 0000110100111101011000100001101001001001111110011000011101101001 | BO33: =VLOOKUP(A33,MESSAGE, 4,FALSE) -> 1110011001100000101100001100001101000111100001010110001010101111
B34: =MID($B33,B$1,1) -> 0 | C34: =MID($B33,C$1,1) -> 0 | D34: =MID($B33,D$1,1) -> 0 | E34: =MID($B33,E$1,1) -> 0 | F34: =MID($B33,F$1,1) -> 1 | G34: =MID($B33,G$1,1) -> 1 | H34: =MID($B33,H$1,1) -> 0 | I34: =MID($B33,I$1,1) -> 1 | ... BM34: =MID($B33,BM$1,1) -> 1 | BO34: =MID($BO33,BO$1,1) -> 1 | BP34: =MID($BO33,BP$1,1) -> 1 | BQ34: =MID($BO33,BQ$1,1) -> 1 | BR34: =MID($BO33,BR$1,1) -> 0 | BS34: =MID($BO33,BS$1,1) -> 0 | BT34: =MID($BO33,BT$1,1) -> 1 | BU34: =MID($BO33,BU$1,1) -> 1 | BV34: =MID($BO33,BV$1,1) -> 0 | ... DZ34: =MID($BO33,DZ$1,1) -> 1 | EB34: =IF(B34=BO34,0,1) -> 1 | EC34: =IF(C34=BP34,0,1) -> 1 | ED34: =IF(D34=BQ34,0,1) -> 1 | EE34: =IF(E34=BR34,0,1) -> 0 | EF34: =IF(F34=BS34,0,1) -> 1 | EG34: =IF(G34=BT34,0,1) -> 0 | EH34: =IF(H34=BU34,0,1) -> 1 | EI34: =IF(I34=BV34,0,1) -> 1 | ... GM34: =IF(BM34=DZ34,0,1) -> 0 | GO34: =SUM(EB34:GM34) -> 37
A35: 16 | B35: =VLOOKUP(A35,MESSAGE,2,FALSE) -> 1111110110100010001110011110001000001101001111010110001000011010 | BO35: =VLOOKUP(A35,MESSAGE, 4,FALSE) -> 1101101011001110001100001010100011100110011000001011000011000011
B36: =MID($B35,B$1,1) -> 1 | C36: =MID($B35,C$1,1) -> 1 | D36: =MID($B35,D$1,1) -> 1 | E36: =MID($B35,E$1,1) -> 1 | F36: =MID($B35,F$1,1) -> 1 | G36: =MID($B35,G$1,1) -> 1 | H36: =MID($B35,H$1,1) -> 0 | I36: =MID($B35,I$1,1) -> 1 | ... BM36: =MID($B35,BM$1,1) -> 0 | BO36: =MID($BO35,BO$1,1) -> 1 | BP36: =MID($BO35,BP$1,1) -> 1 | BQ36: =MID($BO35,BQ$1,1) -> 0 | BR36: =MID($BO35,BR$1,1) -> 1 | BS36: =MID($BO35,BS$1,1) -> 1 | BT36: =MID($BO35,BT$1,1) -> 0 | BU36: =MID($BO35,BU$1,1) -> 1 | BV36: =MID($BO35,BV$1,1) -> 0 | ... DZ36: =MID($BO35,DZ$1,1) -> 1 | EB36: =IF(B36=BO36,0,1) -> 0 | EC36: =IF(C36=BP36,0,1) -> 0 | ED36: =IF(D36=BQ36,0,1) -> 1 | EE36: =IF(E36=BR36,0,1) -> 0 | EF36: =IF(F36=BS36,0,1) -> 0 | EG36: =IF(G36=BT36,0,1) -> 1 | EH36: =IF(H36=BU36,0,1) -> 1 | EI36: =IF(I36=BV36,0,1) -> 1 | ... GM36: =IF(BM36=DZ36,0,1) -> 1 | GO36: =SUM(EB36:GM36) -> 33
C38: STANDARD DES PROCESS

Sheet CiDi SHEET
B1: REF | C1: 1 | D1: 2 | E1: 3 | F1: 4 | G1: 5 | H1: 6 | I1: 7 | J1: CONCATENATED
A2: K+ | B2: 1 | C2: =MID('IO SHEET'!$B$11,VLOOKUP($B2,PC_1,'CiDi SHEET'!C$1+1,FALSE),1) -> 1 | D2: =MID('IO SHEET'!$B$11,VLOOKUP($B2,PC_1,'CiDi SHEET'!D$1+1,FALSE),1) -> 1 | E2: =MID('IO SHEET'!$B$11,VLOOKUP($B2,PC_1,'CiDi SHEET'!E$1+1,FALSE),1) -> 0 | F2: =MID('IO SHEET'!$B$11,VLOOKUP($B2,PC_1,'CiDi SHEET'!F$1+1,FALSE),1) -> 0 | G2: =MID('IO SHEET'!$B$11,VLOOKUP($B2,PC_1,'CiDi SHEET'!G$1+1,FALSE),1) -> 0 | H2: =MID('IO SHEET'!$B$11,VLOOKUP($B2,PC_1,'CiDi SHEET'!H$1+1,FALSE),1) -> 0 | I2: =MID('IO SHEET'!$B$11,VLOOKUP($B2,PC_1,'CiDi SHEET'!I$1+1,FALSE),1) -> 1 | J2: =CONCATENATE(C2,D2,E2,F2,G2,H2,I2) -> 1100001
B3: 2 | C3: =MID('IO SHEET'!$B$11,VLOOKUP($B3,PC_1,'CiDi SHEET'!C$1+1,FALSE),1) -> 1 | D3: =MID('IO SHEET'!$B$11,VLOOKUP($B3,PC_1,'CiDi SHEET'!D$1+1,FALSE),1) -> 1 | E3: =MID('IO SHEET'!$B$11,VLOOKUP($B3,PC_1,'CiDi SHEET'!E$1+1,FALSE),1) -> 1 | F3: =MID('IO SHEET'!$B$11,VLOOKUP($B3,PC_1,'CiDi SHEET'!F$1+1,FALSE),1) -> 0 | G3: =MID('IO SHEET'!$B$11,VLOOKUP($B3,PC_1,'CiDi SHEET'!G$1+1,FALSE),1) -> 0 | H3: =MID('IO SHEET'!$B$11,VLOOKUP($B3,PC_1,'CiDi SHEET'!H$1+1,FALSE),1) -> 0 | I3: =MID('IO SHEET'!$B$11,VLOOKUP($B3,PC_1,'CiDi SHEET'!I$1+1,FALSE),1) -> 0 | J3: =CONCATENATE(C3,D3,E3,F3,G3,H3,I3) -> 1110000
B4: 3 | C4: =MID('IO SHEET'!$B$11,VLOOKUP($B4,PC_1,'CiDi SHEET'!C$1+1,FALSE),1) -> 0 | D4: =MID('IO SHEET'!$B$11,VLOOKUP($B4,PC_1,'CiDi SHEET'!D$1+1,FALSE),1) -> 0 | E4: =MID('IO SHEET'!$B$11,VLOOKUP($B4,PC_1,'CiDi SHEET'!E$1+1,FALSE),1) -> 0 | F4: =MID('IO SHEET'!$B$11,VLOOKUP($B4,PC_1,'CiDi SHEET'!F$1+1,FALSE),1) -> 0 | G4: =MID('IO SHEET'!$B$11,VLOOKUP($B4,PC_1,'CiDi SHEET'!G$1+1,FALSE),1) -> 1 | H4: =MID('IO SHEET'!$B$11,VLOOKUP($B4,PC_1,'CiDi SHEET'!H$1+1,FALSE),1) -> 1 | I4: =MID('IO SHEET'!$B$11,VLOOKUP($B4,PC_1,'CiDi SHEET'!I$1+1,FALSE),1) -> 0 | J4: =CONCATENATE(C4,D4,E4,F4,G4,H4,I4) -> 0000110
B5: 4 | C5: =MID('IO SHEET'!$B$11,VLOOKUP($B5,PC_1,'CiDi SHEET'!C$1+1,FALSE),1) -> 0 | D5: =MID('IO SHEET'!$B$11,VLOOKUP($B5,PC_1,'CiDi SHEET'!D$1+1,FALSE),1) -> 1 | E5: =MID('IO SHEET'!$B$11,VLOOKUP($B5,PC_1,'CiDi SHEET'!E$1+1,FALSE),1) -> 1 | F5: =MID('IO SHEET'!$B$11,VLOOKUP($B5,PC_1,'CiDi SHEET'!F$1+1,FALSE),1) -> 1 | G5: =MID('IO SHEET'!$B$11,VLOOKUP($B5,PC_1,'CiDi SHEET'!G$1+1,FALSE),1) -> 0 | H5: =MID('IO SHEET'!$B$11,VLOOKUP($B5,PC_1,'CiDi SHEET'!H$1+1,FALSE),1) -> 1 | I5: =MID('IO SHEET'!$B$11,VLOOKUP($B5,PC_1,'CiDi SHEET'!I$1+1,FALSE),1) -> 0 | J5: =CONCATENATE(C5,D5,E5,F5,G5,H5,I5) -> 0111010
B6: 5 | C6: =MID('IO SHEET'!$B$11,VLOOKUP($B6,PC_1,'CiDi SHEET'!C$1+1,FALSE),1) -> 0 | D6: =MID('IO SHEET'!$B$11,VLOOKUP($B6,PC_1,'CiDi SHEET'!D$1+1,FALSE),1) -> 0 | E6: =MID('IO SHEET'!$B$11,VLOOKUP($B6,PC_1,'CiDi SHEET'!E$1+1,FALSE),1) -> 1 | F6: =MID('IO SHEET'!$B$11,VLOOKUP($B6,PC_1,'CiDi SHEET'!F$1+1,FALSE),1) -> 1 | G6: =MID('IO SHEET'!$B$11,VLOOKUP($B6,PC_1,'CiDi SHEET'!G$1+1,FALSE),1) -> 0 | H6: =MID('IO SHEET'!$B$11,VLOOKUP($B6,PC_1,'CiDi SHEET'!H$1+1,FALSE),1) -> 0 | I6: =MID('IO SHEET'!$B$11,VLOOKUP($B6,PC_1,'CiDi SHEET'!I$1+1,FALSE),1) -> 1 | J6: =CONCATENATE(C6,D6,E6,F6,G6,H6,I6) -> 0011001
B7: 6 | C7: =MID('IO SHEET'!$B$11,VLOOKUP($B7,PC_1,'CiDi SHEET'!C$1+1,FALSE),1) -> 1 | D7: =MID('IO SHEET'!$B$11,VLOOKUP($B7,PC_1,'CiDi SHEET'!D$1+1,FALSE),1) -> 1 | E7: =MID('IO SHEET'!$B$11,VLOOKUP($B7,PC_1,'CiDi SHEET'!E$1+1,FALSE),1) -> 1 | F7: =MID('IO SHEET'!$B$11,VLOOKUP($B7,PC_1,'CiDi SHEET'!F$1+1,FALSE),1) -> 1 | G7: =MID('IO SHEET'!$B$11,VLOOKUP($B7,PC_1,'CiDi SHEET'!G$1+1,FALSE),1) -> 1 | H7: =MID('IO SHEET'!$B$11,VLOOKUP($B7,PC_1,'CiDi SHEET'!H$1+1,FALSE),1) -> 0 | I7: =MID('IO SHEET'!$B$11,VLOOKUP($B7,PC_1,'CiDi SHEET'!I$1+1,FALSE),1) -> 0 | J7: =CONCATENATE(C7,D7,E7,F7,G7,H7,I7) -> 1111100
B8: 7 | C8: =MID('IO SHEET'!$B$11,VLOOKUP($B8,PC_1,'CiDi SHEET'!C$1+1,FALSE),1) -> 0 | D8: =MID('IO SHEET'!$B$11,VLOOKUP($B8,PC_1,'CiDi SHEET'!D$1+1,FALSE),1) -> 0 | E8: =MID('IO SHEET'!$B$11,VLOOKUP($B8,PC_1,'CiDi SHEET'!E$1+1,FALSE),1) -> 1 | F8: =MID('IO SHEET'!$B$11,VLOOKUP($B8,PC_1,'CiDi SHEET'!F$1+1,FALSE),1) -> 1 | G8: =MID('IO SHEET'!$B$11,VLOOKUP($B8,PC_1,'CiDi SHEET'!G$1+1,FALSE),1) -> 0 | H8: =MID('IO SHEET'!$B$11,VLOOKUP($B8,PC_1,'CiDi SHEET'!H$1+1,FALSE),1) -> 0 | I8: =MID('IO SHEET'!$B$11,VLOOKUP($B8,PC_1,'CiDi SHEET'!I$1+1,FALSE),1) -> 1 | J8: =CONCATENATE(C8,D8,E8,F8,G8,H8,I8) -> 0011001
B9: 8 | C9: =MID('IO SHEET'!$B$11,VLOOKUP($B9,PC_1,'CiDi SHEET'!C$1+1,FALSE),1) -> 1 | D9: =MID('IO SHEET'!$B$11,VLOOKUP($B9,PC_1,'CiDi SHEET'!D$1+1,FALSE),1) -> 1 | E9: =MID('IO SHEET'!$B$11,VLOOKUP($B9,PC_1,'CiDi SHEET'!E$1+1,FALSE),1) -> 1 | F9: =MID('IO SHEET'!$B$11,VLOOKUP($B9,PC_1,'CiDi SHEET'!F$1+1,FALSE),1) -> 1 | G9: =MID('IO SHEET'!$B$11,VLOOKUP($B9,PC_1,'CiDi SHEET'!G$1+1,FALSE),1) -> 0 | H9: =MID('IO SHEET'!$B$11,VLOOKUP($B9,PC_1,'CiDi SHEET'!H$1+1,FALSE),1) -> 1 | I9: =MID('IO SHEET'!$B$11,VLOOKUP($B9,PC_1,'CiDi SHEET'!I$1+1,FALSE),1) -> 0 | J9: =CONCATENATE(C9,D9,E9,F9,G9,H9,I9) -> 1111010
A10: K+str | C10: =CONCATENATE(J2,J3,J4,J5,J6,J7,J8,J9) -> 11000011110000000011001110100011001111110000110011111010
C11: =LEN(C10) -> 56
A12: ITERATION | B12: SHIFT | C12: Ci | K12: Di
A13: 0 | B13: 0 | C13: =CONCATENATE(J2,J3,J4,J5) -> 1100001111000000001100111010 | K13: =CONCATENATE(J6,J7,J8,J9) -> 0011001111110000110011111010
A14: 1 | B14: 1 | C14: =CONCATENATE(RIGHT(C13,(28-$B14)),LEFT(C13,$B14)) -> 1000011110000000011001110101 | K14: =CONCATENATE(RIGHT(K13,(28-$B14)),LEFT(K13,$B14)) -> 0110011111100001100111110100
A15: 2 | B15: 1 | C15: =CONCATENATE(RIGHT(C14,(28-$B15)),LEFT(C14,B15)) -> 0000111100000000110011101011 | K15: =CONCATENATE(RIGHT(K14,(28-$B15)),LEFT(K14,$B15)) -> 1100111111000011001111101000
A16: 3 | B16: 2 | C16: =CONCATENATE(RIGHT(C15,(28-$B16)),LEFT(C15,B16)) -> 0011110000000011001110101100 | K16: =CONCATENATE(RIGHT(K15,(28-$B16)),LEFT(K15,$B16)) -> 0011111100001100111110100011
A17: 4 | B17: 2 | C17: =CONCATENATE(RIGHT(C16,(28-$B17)),LEFT(C16,B17)) -> 1111000000001100111010110000 | K17: =CONCATENATE(RIGHT(K16,(28-$B17)),LEFT(K16,$B17)) -> 1111110000110011111010001100
A18: 5 | B18: 2 | C18: =CONCATENATE(RIGHT(C17,(28-$B18)),LEFT(C17,B18)) -> 1100000000110011101011000011 | K18: =CONCATENATE(RIGHT(K17,(28-$B18)),LEFT(K17,$B18)) -> 1111000011001111101000110011
A19: 6 | B19: 2 | C19: =CONCATENATE(RIGHT(C18,(28-$B19)),LEFT(C18,B19)) -> 0000000011001110101100001111 | K19: =CONCATENATE(RIGHT(K18,(28-$B19)),LEFT(K18,$B19)) -> 1100001100111110100011001111
A20: 7 | B20: 2 | C20: =CONCATENATE(RIGHT(C19,(28-$B20)),LEFT(C19,B20)) -> 0000001100111010110000111100 | K20: =CONCATENATE(RIGHT(K19,(28-$B20)),LEFT(K19,$B20)) -> 0000110011111010001100111111
A21: 8 | B21: 2 | C21: =CONCATENATE(RIGHT(C20,(28-$B21)),LEFT(C20,B21)) -> 0000110011101011000011110000 | K21: =CONCATENATE(RIGHT(K20,(28-$B21)),LEFT(K20,$B21)) -> 0011001111101000110011111100
A22: 9 | B22: 1 | C22: =CONCATENATE(RIGHT(C21,(28-$B22)),LEFT(C21,B22)) -> 0001100111010110000111100000 | K22: =CONCATENATE(RIGHT(K21,(28-$B22)),LEFT(K21,$B22)) -> 0110011111010001100111111000
A23: 10 | B23: 2 | C23: =CONCATENATE(RIGHT(C22,(28-$B23)),LEFT(C22,B23)) -> 0110011101011000011110000000 | K23: =CONCATENATE(RIGHT(K22,(28-$B23)),LEFT(K22,$B23)) -> 1001111101000110011111100001
A24: 11 | B24: 2 | C24: =CONCATENATE(RIGHT(C23,(28-$B24)),LEFT(C23,B24)) -> 1001110101100001111000000001 | K24: =CONCATENATE(RIGHT(K23,(28-$B24)),LEFT(K23,$B24)) -> 0111110100011001111110000110
A25: 12 | B25: 2 | C25: =CONCATENATE(RIGHT(C24,(28-$B25)),LEFT(C24,B25)) -> 0111010110000111100000000110 | K25: =CONCATENATE(RIGHT(K24,(28-$B25)),LEFT(K24,$B25)) -> 1111010001100111111000011001
A26: 13 | B26: 2 | C26: =CONCATENATE(RIGHT(C25,(28-$B26)),LEFT(C25,B26)) -> 1101011000011110000000011001 | K26: =CONCATENATE(RIGHT(K25,(28-$B26)),LEFT(K25,$B26)) -> 1101000110011111100001100111
... A28: 15 | B28: 2 | C28: =CONCATENATE(RIGHT(C27,(28-$B28)),LEFT(C27,B28)) -> 0110000111100000000110011101 | K28: =CONCATENATE(RIGHT(K27,(28-$B28)),LEFT(K27,$B28)) -> 0001100111111000011001111101
A29: 16 | B29: 1 | C29: =CONCATENATE(RIGHT(C28,(28-$B29)),LEFT(C28,B29)) -> 1100001111000000001100111010 | K29: =CONCATENATE(RIGHT(K28,(28-$B29)),LEFT(K28,$B29)) -> 0011001111110000110011111010 | S29: 1 | T29: =S29+4 -> 5 | U29: =T29+4 -> 9 | V29: =U29+4 -> 13 | W29: =V29+4 -> 17 | X29: =W29+4 -> 21 | Y29: =X29+4 -> 25 | Z29: =Y29+4 -> 29 | AA29: =Z29+4 -> 33 | ... AD29: =AC29+4 -> 45 | AE29: 49 | AF29: 53
A30: C0D0 | C30: =CONCATENATE(C13,K13) -> 11000011110000000011001110100011001111110000110011111010 | S30: =MID($C30,S$29,4) -> 1100 | T30: =MID($C30,T$29,4) -> 0011 | U30: =MID($C30,U$29,4) -> 1100 | V30: =MID($C30,V$29,4) -> 0000 | W30: =MID($C30,W$29,4) -> 0011 | X30: =MID($C30,X$29,4) -> 0011 | Y30: =MID($C30,Y$29,4) -> 1010 | Z30: =MID($C30,Z$29,4) -> 0011 | ... AF30: =MID($C30,AF$29,4) -> 1010 | AG30: =BIN2HEX(S30) -> C | AH30: =BIN2HEX(T30) -> 3 | AI30: =BIN2HEX(U30) -> C | AJ30: =BIN2HEX(V30) -> 0 | AK30: =BIN2HEX(W30) -> 3 | AL30: =BIN2HEX(X30) -> 3 | AM30: =BIN2HEX(Y30) -> A | AN30: =BIN2HEX(Z30) -> 3 | ... AT30: =BIN2HEX(AF30) -> A
A31: C1D1 | C31: =CONCATENATE(C14,K14) -> 10000111100000000110011101010110011111100001100111110100 | S31: =MID($C31,S$29,4) -> 1000 | T31: =MID($C31,T$29,4) -> 0111 | U31: =MID($C31,U$29,4) -> 1000 | V31: =MID($C31,V$29,4) -> 0000 | W31: =MID($C31,W$29,4) -> 0110 | X31: =MID($C31,X$29,4) -> 0111 | Y31: =MID($C31,Y$29,4) -> 0101 | Z31: =MID($C31,Z$29,4) -> 0110 | ... AF31: =MID($C31,AF$29,4) -> 0100 | AG31: =BIN2HEX(S31) -> 8 | AH31: =BIN2HEX(T31) -> 7 | AI31: =BIN2HEX(U31) -> 8 | AJ31: =BIN2HEX(V31) -> 0 | AK31: =BIN2HEX(W31) -> 6 | AL31: =BIN2HEX(X31) -> 7 | AM31: =BIN2HEX(Y31) -> 5 | AN31: =BIN2HEX(Z31) -> 6 | ... AT31: =BIN2HEX(AF31) -> 4
A32: C2D2 | C32: =CONCATENATE(C15,K15) -> 00001111000000001100111010111100111111000011001111101000 | S32: =MID($C32,S$29,4) -> 0000 | T32: =MID($C32,T$29,4) -> 1111 | U32: =MID($C32,U$29,4) -> 0000 | V32: =MID($C32,V$29,4) -> 0000 | W32: =MID($C32,W$29,4) -> 1100 | X32: =MID($C32,X$29,4) -> 1110 | Y32: =MID($C32,Y$29,4) -> 1011 | Z32: =MID($C32,Z$29,4) -> 1100 | ... AF32: =MID($C32,AF$29,4) -> 1000 | AG32: =BIN2HEX(S32) -> 0 | AH32: =BIN2HEX(T32) -> F | AI32: =BIN2HEX(U32) -> 0 | AJ32: =BIN2HEX(V32) -> 0 | AK32: =BIN2HEX(W32) -> C | AL32: =BIN2HEX(X32) -> E | AM32: =BIN2HEX(Y32) -> B | AN32: =BIN2HEX(Z32) -> C | ... AT32: =BIN2HEX(AF32) -> 8
A33: C3D3 | C33: =CONCATENATE(C16,K16) -> 00111100000000110011101011000011111100001100111110100011 | S33: =MID($C33,S$29,4) -> 0011 | T33: =MID($C33,T$29,4) -> 1100 | U33: =MID($C33,U$29,4) -> 0000 | V33: =MID($C33,V$29,4) -> 0011 | W33: =MID($C33,W$29,4) -> 0011 | X33: =MID($C33,X$29,4) -> 1010 | Y33: =MID($C33,Y$29,4) -> 1100 | Z33: =MID($C33,Z$29,4) -> 0011 | ... AF33: =MID($C33,AF$29,4) -> 0011 | AG33: =BIN2HEX(S33) -> 3 | AH33: =BIN2HEX(T33) -> C | AI33: =BIN2HEX(U33) -> 0 | AJ33: =BIN2HEX(V33) -> 3 | AK33: =BIN2HEX(W33) -> 3 | AL33: =BIN2HEX(X33) -> A | AM33: =BIN2HEX(Y33) -> C | AN33: =BIN2HEX(Z33) -> 3 | ... AT33: =BIN2HEX(AF33) -> 3
A34: C4D4 | C34: =CONCATENATE(C17,K17) -> 11110000000011001110101100001111110000110011111010001100 | S34: =MID($C34,S$29,4) -> 1111 | T34: =MID($C34,T$29,4) -> 0000 | U34: =MID($C34,U$29,4) -> 0000 | V34: =MID($C34,V$29,4) -> 1100 | W34: =MID($C34,W$29,4) -> 1110 | X34: =MID($C34,X$29,4) -> 1011 | Y34: =MID($C34,Y$29,4) -> 0000 | Z34: =MID($C34,Z$29,4) -> 1111 | ... AF34: =MID($C34,AF$29,4) -> 1100 | AG34: =BIN2HEX(S34) -> F | AH34: =BIN2HEX(T34) -> 0 | AI34: =BIN2HEX(U34) -> 0 | AJ34: =BIN2HEX(V34) -> C | AK34: =BIN2HEX(W34) -> E | AL34: =BIN2HEX(X34) -> B | AM34: =BIN2HEX(Y34) -> 0 | AN34: =BIN2HEX(Z34) -> F | ... AT34: =BIN2HEX(AF34) -> C
A35: C5D5 | C35: =CONCATENATE(C18,K18) -> 11000000001100111010110000111111000011001111101000110011 | S35: =MID($C35,S$29,4) -> 1100 | T35: =MID($C35,T$29,4) -> 0000 | U35: =MID($C35,U$29,4) -> 0011 | V35: =MID($C35,V$29,4) -> 0011 | W35: =MID($C35,W$29,4) -> 1010 | X35: =MID($C35,X$29,4) -> 1100 | Y35: =MID($C35,Y$29,4) -> 0011 | Z35: =MID($C35,Z$29,4) -> 1111 | ... AF35: =MID($C35,AF$29,4) -> 0011 | AG35: =BIN2HEX(S35) -> C | AH35: =BIN2HEX(T35) -> 0 | AI35: =BIN2HEX(U35) -> 3 | AJ35: =BIN2HEX(V35) -> 3 | AK35: =BIN2HEX(W35) -> A | AL35: =BIN2HEX(X35) -> C | AM35: =BIN2HEX(Y35) -> 3 | AN35: =BIN2HEX(Z35) -> F | ... AT35: =BIN2HEX(AF35) -> 3
A36: C6D6 | C36: =CONCATENATE(C19,K19) -> 00000000110011101011000011111100001100111110100011001111 | S36: =MID($C36,S$29,4) -> 0000 | T36: =MID($C36,T$29,4) -> 0000 | U36: =MID($C36,U$29,4) -> 1100 | V36: =MID($C36,V$29,4) -> 1110 | W36: =MID($C36,W$29,4) -> 1011 | X36: =MID($C36,X$29,4) -> 0000 | Y36: =MID($C36,Y$29,4) -> 1111 | Z36: =MID($C36,Z$29,4) -> 1100 | ... AF36: =MID($C36,AF$29,4) -> 1111 | AG36: =BIN2HEX(S36) -> 0 | AH36: =BIN2HEX(T36) -> 0 | AI36: =BIN2HEX(U36) -> C | AJ36: =BIN2HEX(V36) -> E | AK36: =BIN2HEX(W36) -> B | AL36: =BIN2HEX(X36) -> 0 | AM36: =BIN2HEX(Y36) -> F | AN36: =BIN2HEX(Z36) -> C | ... AT36: =BIN2HEX(AF36) -> F
A37: C7D7 | C37: =CONCATENATE(C20,K20) -> 00000011001110101100001111000000110011111010001100111111 | S37: =MID($C37,S$29,4) -> 0000 | T37: =MID($C37,T$29,4) -> 0011 | U37: =MID($C37,U$29,4) -> 0011 | V37: =MID($C37,V$29,4) -> 1010 | W37: =MID($C37,W$29,4) -> 1100 | X37: =MID($C37,X$29,4) -> 0011 | Y37: =MID($C37,Y$29,4) -> 1100 | Z37: =MID($C37,Z$29,4) -> 0000 | ... AF37: =MID($C37,AF$29,4) -> 1111 | AG37: =BIN2HEX(S37) -> 0 | AH37: =BIN2HEX(T37) -> 3 | AI37: =BIN2HEX(U37) -> 3 | AJ37: =BIN2HEX(V37) -> A | AK37: =BIN2HEX(W37) -> C | AL37: =BIN2HEX(X37) -> 3 | AM37: =BIN2HEX(Y37) -> C | AN37: =BIN2HEX(Z37) -> 0 | ... AT37: =BIN2HEX(AF37) -> F
A38: C8D8 | C38: =CONCATENATE(C21,K21) -> 00001100111010110000111100000011001111101000110011111100 | S38: =MID($C38,S$29,4) -> 0000 | T38: =MID($C38,T$29,4) -> 1100 | U38: =MID($C38,U$29,4) -> 1110 | V38: =MID($C38,V$29,4) -> 1011 | W38: =MID($C38,W$29,4) -> 0000 | X38: =MID($C38,X$29,4) -> 1111 | Y38: =MID($C38,Y$29,4) -> 0000 | Z38: =MID($C38,Z$29,4) -> 0011 | ... AF38: =MID($C38,AF$29,4) -> 1100 | AG38: =BIN2HEX(S38) -> 0 | AH38: =BIN2HEX(T38) -> C | AI38: =BIN2HEX(U38) -> E | AJ38: =BIN2HEX(V38) -> B | AK38: =BIN2HEX(W38) -> 0 | AL38: =BIN2HEX(X38) -> F | AM38: =BIN2HEX(Y38) -> 0 | AN38: =BIN2HEX(Z38) -> 3 | ... AT38: =BIN2HEX(AF38) -> C
A39: C9D9 | C39: =CONCATENATE(C22,K22) -> 00011001110101100001111000000110011111010001100111111000 | S39: =MID($C39,S$29,4) -> 0001 | T39: =MID($C39,T$29,4) -> 1001 | U39: =MID($C39,U$29,4) -> 1101 | V39: =MID($C39,V$29,4) -> 0110 | W39: =MID($C39,W$29,4) -> 0001 | X39: =MID($C39,X$29,4) -> 1110 | Y39: =MID($C39,Y$29,4) -> 0000 | Z39: =MID($C39,Z$29,4) -> 0110 | ... AF39: =MID($C39,AF$29,4) -> 1000 | AG39: =BIN2HEX(S39) -> 1 | AH39: =BIN2HEX(T39) -> 9 | AI39: =BIN2HEX(U39) -> D | AJ39: =BIN2HEX(V39) -> 6 | AK39: =BIN2HEX(W39) -> 1 | AL39: =BIN2HEX(X39) -> E | AM39: =BIN2HEX(Y39) -> 0 | AN39: =BIN2HEX(Z39) -> 6 | ... AT39: =BIN2HEX(AF39) -> 8
A40: C10D10 | C40: =CONCATENATE(C23,K23) -> 01100111010110000111100000001001111101000110011111100001 | S40: =MID($C40,S$29,4) -> 0110 | T40: =MID($C40,T$29,4) -> 0111 | U40: =MID($C40,U$29,4) -> 0101 | V40: =MID($C40,V$29,4) -> 1000 | W40: =MID($C40,W$29,4) -> 0111 | X40: =MID($C40,X$29,4) -> 1000 | Y40: =MID($C40,Y$29,4) -> 0000 | Z40: =MID($C40,Z$29,4) -> 1001 | ... AF40: =MID($C40,AF$29,4) -> 0001 | AG40: =BIN2HEX(S40) -> 6 | AH40: =BIN2HEX(T40) -> 7 | AI40: =BIN2HEX(U40) -> 5 | AJ40: =BIN2HEX(V40) -> 8 | AK40: =BIN2HEX(W40) -> 7 | AL40: =BIN2HEX(X40) -> 8 | AM40: =BIN2HEX(Y40) -> 0 | AN40: =BIN2HEX(Z40) -> 9 | ... AT40: =BIN2HEX(AF40) -> 1
A41: C11D11 | C41: =CONCATENATE(C24,K24) -> 10011101011000011110000000010111110100011001111110000110 | S41: =MID($C41,S$29,4) -> 1001 | T41: =MID($C41,T$29,4) -> 1101 | U41: =MID($C41,U$29,4) -> 0110 | V41: =MID($C41,V$29,4) -> 0001 | W41: =MID($C41,W$29,4) -> 1110 | X41: =MID($C41,X$29,4) -> 0000 | Y41: =MID($C41,Y$29,4) -> 0001 | Z41: =MID($C41,Z$29,4) -> 0111 | ... AF41: =MID($C41,AF$29,4) -> 0110 | AG41: =BIN2HEX(S41) -> 9 | AH41: =BIN2HEX(T41) -> D | AI41: =BIN2HEX(U41) -> 6 | AJ41: =BIN2HEX(V41) -> 1 | AK41: =BIN2HEX(W41) -> E | AL41: =BIN2HEX(X41) -> 0 | AM41: =BIN2HEX(Y41) -> 1 | AN41: =BIN2HEX(Z41) -> 7 | ... AT41: =BIN2HEX(AF41) -> 6
...

Sheet Kn
C1: 1 | D1: 2 | E1: 3 | F1: 4 | G1: 5 | H1: 6 | I1: CONCATENATED | N1: Kn | O1: String | AA1: 1 | AB1: =AA1+4 -> 5 | AC1: =AB1+4 -> 9 | AD1: =AC1+4 -> 13 | AE1: =AD1+4 -> 17 | AF1: =AE1+4 -> 21 | AG1: =AF1+4 -> 25 | AH1: =AG1+4 -> 29 | AI1: =AH1+4 -> 33 | ... AL1: =AK1+4 -> 45
A2: K1 | B2: 1 | C2: =MID('CiDi SHEET'!$C$31,VLOOKUP($B2,PC_2,C$1+1,FALSE),1) -> 0 | D2: =MID('CiDi SHEET'!$C$31,VLOOKUP($B2,PC_2,D$1+1,FALSE),1) -> 0 | E2: =MID('CiDi SHEET'!$C$31,VLOOKUP($B2,PC_2,E$1+1,FALSE),1) -> 0 | F2: =MID('CiDi SHEET'!$C$31,VLOOKUP($B2,PC_2,F$1+1,FALSE),1) -> 1 | G2: =MID('CiDi SHEET'!$C$31,VLOOKUP($B2,PC_2,G$1+1,FALSE),1) -> 1 | H2: =MID('CiDi SHEET'!$C$31,VLOOKUP($B2,PC_2,H$1+1,FALSE),1) -> 0 | I2: =CONCATENATE(C2,D2,E2,F2,G2,H2) -> 000110 | N2: K1 | O2: =B10 -> 000110010100110011010000011100101101111010001100 | AA2: =MID($O2,AA$1,4) -> 0001 | AB2: =MID($O2,AB$1,4) -> 1001 | AC2: =MID($O2,AC$1,4) -> 0100 | AD2: =MID($O2,AD$1,4) -> 1100 | AE2: =MID($O2,AE$1,4) -> 1101 | AF2: =MID($O2,AF$1,4) -> 0000 | AG2: =MID($O2,AG$1,4) -> 0111 | AH2: =MID($O2,AH$1,4) -> 0010 | ... AL2: =MID($O2,AL$1,4) -> 1100 | AM2: =BIN2HEX(AA2) -> 1 | AN2: =BIN2HEX(AB2) -> 9 | AO2: =BIN2HEX(AC2) -> 4 | AP2: =BIN2HEX(AD2) -> C | AQ2: =BIN2HEX(AE2) -> D | AR2: =BIN2HEX(AF2) -> 0 | AS2: =BIN2HEX(AG2) -> 7 | AT2: =BIN2HEX(AH2) -> 2 | ... AX2: =BIN2HEX(AL2) -> C
B3: 2 | C3: =MID('CiDi SHEET'!$C$31,VLOOKUP($B3,PC_2,C$1+1,FALSE),1) -> 0 | D3: =MID('CiDi SHEET'!$C$31,VLOOKUP($B3,PC_2,D$1+1,FALSE),1) -> 1 | E3: =MID('CiDi SHEET'!$C$31,VLOOKUP($B3,PC_2,E$1+1,FALSE),1) -> 0 | F3: =MID('CiDi SHEET'!$C$31,VLOOKUP($B3,PC_2,F$1+1,FALSE),1) -> 1 | G3: =MID('CiDi SHEET'!$C$31,VLOOKUP($B3,PC_2,G$1+1,FALSE),1) -> 0 | H3: =MID('CiDi SHEET'!$C$31,VLOOKUP($B3,PC_2,H$1+1,FALSE),1) -> 0 | I3: =CONCATENATE(C3,D3,E3,F3,G3,H3) -> 010100 | N3: K2 | O3: =B19 -> 010001010110100001011000000110101011110011001110 | AA3: =MID($O3,AA$1,4) -> 0100 | AB3: =MID($O3,AB$1,4) -> 0101 | AC3: =MID($O3,AC$1,4) -> 0110 | AD3: =MID($O3,AD$1,4) -> 1000 | AE3: =MID($O3,AE$1,4) -> 0101 | AF3: =MID($O3,AF$1,4) -> 1000 | AG3: =MID($O3,AG$1,4) -> 0001 | AH3: =MID($O3,AH$1,4) -> 1010 | ... AL3: =MID($O3,AL$1,4) -> 1110 | AM3: =BIN2HEX(AA3) -> 4 | AN3: =BIN2HEX(AB3) -> 5 | AO3: =BIN2HEX(AC3) -> 6 | AP3: =BIN2HEX(AD3) -> 8 | AQ3: =BIN2HEX(AE3) -> 5 | AR3: =BIN2HEX(AF3) -> 8 | AS3: =BIN2HEX(AG3) -> 1 | AT3: =BIN2HEX(AH3) -> A | ... AX3: =BIN2HEX(AL3) -> E
B4: 3 | C4: =MID('CiDi SHEET'!$C$31,VLOOKUP($B4,PC_2,C$1+1,FALSE),1) -> 1 | D4: =MID('CiDi SHEET'!$C$31,VLOOKUP($B4,PC_2,D$1+1,FALSE),1) -> 1 | E4: =MID('CiDi SHEET'!$C$31,VLOOKUP($B4,PC_2,E$1+1,FALSE),1) -> 0 | F4: =MID('CiDi SHEET'!$C$31,VLOOKUP($B4,PC_2,F$1+1,FALSE),1) -> 0 | G4: =MID('CiDi SHEET'!$C$31,VLOOKUP($B4,PC_2,G$1+1,FALSE),1) -> 1 | H4: =MID('CiDi SHEET'!$C$31,VLOOKUP($B4,PC_2,H$1+1,FALSE),1) -> 1 | I4: =CONCATENATE(C4,D4,E4,F4,G4,H4) -> 110011 | N4: K3 | O4: =B28 -> 000001101110110110100100101011001111010110110101 | AA4: =MID($O4,AA$1,4) -> 0000 | AB4: =MID($O4,AB$1,4) -> 0110 | AC4: =MID($O4,AC$1,4) -> 1110 | AD4: =MID($O4,AD$1,4) -> 1101 | AE4: =MID($O4,AE$1,4) -> 1010 | AF4: =MID($O4,AF$1,4) -> 0100 | AG4: =MID($O4,AG$1,4) -> 1010 | AH4: =MID($O4,AH$1,4) -> 1100 | ... AL4: =MID($O4,AL$1,4) -> 0101 | AM4: =BIN2HEX(AA4) -> 0 | AN4: =BIN2HEX(AB4) -> 6 | AO4: =BIN2HEX(AC4) -> E | AP4: =BIN2HEX(AD4) -> D | AQ4: =BIN2HEX(AE4) -> A | AR4: =BIN2HEX(AF4) -> 4 | AS4: =BIN2HEX(AG4) -> A | AT4: =BIN2HEX(AH4) -> C | ... AX4: =BIN2HEX(AL4) -> 5
B5: 4 | C5: =MID('CiDi SHEET'!$C$31,VLOOKUP($B5,PC_2,C$1+1,FALSE),1) -> 0 | D5: =MID('CiDi SHEET'!$C$31,VLOOKUP($B5,PC_2,D$1+1,FALSE),1) -> 1 | E5: =MID('CiDi SHEET'!$C$31,VLOOKUP($B5,PC_2,E$1+1,FALSE),1) -> 0 | F5: =MID('CiDi SHEET'!$C$31,VLOOKUP($B5,PC_2,F$1+1,FALSE),1) -> 0 | G5: =MID('CiDi SHEET'!$C$31,VLOOKUP($B5,PC_2,G$1+1,FALSE),1) -> 0 | H5: =MID('CiDi SHEET'!$C$31,VLOOKUP($B5,PC_2,H$1+1,FALSE),1) -> 0 | I5: =CONCATENATE(C5,D5,E5,F5,G5,H5) -> 010000 | N5: K4 | O5: =B37 -> 110110100010110100000011001010110110111011100011 | AA5: =MID($O5,AA$1,4) -> 1101 | AB5: =MID($O5,AB$1,4) -> 1010 | AC5: =MID($O5,AC$1,4) -> 0010 | AD5: =MID($O5,AD$1,4) -> 1101 | AE5: =MID($O5,AE$1,4) -> 0000 | AF5: =MID($O5,AF$1,4) -> 0011 | AG5: =MID($O5,AG$1,4) -> 0010 | AH5: =MID($O5,AH$1,4) -> 1011 | ... AL5: =MID($O5,AL$1,4) -> 0011 | AM5: =BIN2HEX(AA5) -> D | AN5: =BIN2HEX(AB5) -> A | AO5: =BIN2HEX(AC5) -> 2 | AP5: =BIN2HEX(AD5) -> D | AQ5: =BIN2HEX(AE5) -> 0 | AR5: =BIN2HEX(AF5) -> 3 | AS5: =BIN2HEX(AG5) -> 2 | AT5: =BIN2HEX(AH5) -> B | ... AX5: =BIN2HEX(AL5) -> 3
B6: 5 | C6: =MID('CiDi SHEET'!$C$31,VLOOKUP($B6,PC_2,C$1+1,FALSE),1) -> 0 | D6: =MID('CiDi SHEET'!$C$31,VLOOKUP($B6,PC_2,D$1+1,FALSE),1) -> 1 | E6: =MID('CiDi SHEET'!$C$31,VLOOKUP($B6,PC_2,E$1+1,FALSE),1) -> 1 | F6: =MID('CiDi SHEET'!$C$31,VLOOKUP($B6,PC_2,F$1+1,FALSE),1) -> 1 | G6: =MID('CiDi SHEET'!$C$31,VLOOKUP($B6,PC_2,G$1+1,FALSE),1) -> 0 | H6: =MID('CiDi SHEET'!$C$31,VLOOKUP($B6,PC_2,H$1+1,FALSE),1) -> 0 | I6: =CONCATENATE(C6,D6,E6,F6,G6,H6) -> 011100 | N6: K5 | O6: =B46 -> 011010011010011000101001111111101100100100010011 | AA6: =MID($O6,AA$1,4) -> 0110 | AB6: =MID($O6,AB$1,4) -> 1001 | AC6: =MID($O6,AC$1,4) -> 1010 | AD6: =MID($O6,AD$1,4) -> 0110 | AE6: =MID($O6,AE$1,4) -> 0010 | AF6: =MID($O6,AF$1,4) -> 1001 | AG6: =MID($O6,AG$1,4) -> 1111 | AH6: =MID($O6,AH$1,4) -> 1110 | ... AL6: =MID($O6,AL$1,4) -> 0011 | AM6: =BIN2HEX(AA6) -> 6 | AN6: =BIN2HEX(AB6) -> 9 | AO6: =BIN2HEX(AC6) -> A | AP6: =BIN2HEX(AD6) -> 6 | AQ6: =BIN2HEX(AE6) -> 2 | AR6: =BIN2HEX(AF6) -> 9 | AS6: =BIN2HEX(AG6) -> F | AT6: =BIN2HEX(AH6) -> E | ... AX6: =BIN2HEX(AL6) -> 3
B7: 6 | C7: =MID('CiDi SHEET'!$C$31,VLOOKUP($B7,PC_2,C$1+1,FALSE),1) -> 1 | D7: =MID('CiDi SHEET'!$C$31,VLOOKUP($B7,PC_2,D$1+1,FALSE),1) -> 0 | E7: =MID('CiDi SHEET'!$C$31,VLOOKUP($B7,PC_2,E$1+1,FALSE),1) -> 1 | F7: =MID('CiDi SHEET'!$C$31,VLOOKUP($B7,PC_2,F$1+1,FALSE),1) -> 1 | G7: =MID('CiDi SHEET'!$C$31,VLOOKUP($B7,PC_2,G$1+1,FALSE),1) -> 0 | H7: =MID('CiDi SHEET'!$C$31,VLOOKUP($B7,PC_2,H$1+1,FALSE),1) -> 1 | I7: =CONCATENATE(C7,D7,E7,F7,G7,H7) -> 101101 | N7: K6 | O7: =B55 -> 110000011001010010001110100001110100011101011110 | AA7: =MID($O7,AA$1,4) -> 1100 | AB7: =MID($O7,AB$1,4) -> 0001 | AC7: =MID($O7,AC$1,4) -> 1001 | AD7: =MID($O7,AD$1,4) -> 0100 | AE7: =MID($O7,AE$1,4) -> 1000 | AF7: =MID($O7,AF$1,4) -> 1110 | AG7: =MID($O7,AG$1,4) -> 1000 | AH7: =MID($O7,AH$1,4) -> 0111 | ... AL7: =MID($O7,AL$1,4) -> 1110 | AM7: =BIN2HEX(AA7) -> C | AN7: =BIN2HEX(AB7) -> 1 | AO7: =BIN2HEX(AC7) -> 9 | AP7: =BIN2HEX(AD7) -> 4 | AQ7: =BIN2HEX(AE7) -> 8 | AR7: =BIN2HEX(AF7) -> E | AS7: =BIN2HEX(AG7) -> 8 | AT7: =BIN2HEX(AH7) -> 7 | ... AX7: =BIN2HEX(AL7) -> E
B8: 7 | C8: =MID('CiDi SHEET'!$C$31,VLOOKUP($B8,PC_2,C$1+1,FALSE),1) -> 1 | D8: =MID('CiDi SHEET'!$C$31,VLOOKUP($B8,PC_2,D$1+1,FALSE),1) -> 1 | E8: =MID('CiDi SHEET'!$C$31,VLOOKUP($B8,PC_2,E$1+1,FALSE),1) -> 1 | F8: =MID('CiDi SHEET'!$C$31,VLOOKUP($B8,PC_2,F$1+1,FALSE),1) -> 0 | G8: =MID('CiDi SHEET'!$C$31,VLOOKUP($B8,PC_2,G$1+1,FALSE),1) -> 1 | H8: =MID('CiDi SHEET'!$C$31,VLOOKUP($B8,PC_2,H$1+1,FALSE),1) -> 0 | I8: =CONCATENATE(C8,D8,E8,F8,G8,H8) -> 111010 | N8: K7 | O8: =B64 -> 011100001000101011010010110111011011001111000000 | AA8: =MID($O8,AA$1,4) -> 0111 | AB8: =MID($O8,AB$1,4) -> 0000 | AC8: =MID($O8,AC$1,4) -> 1000 | AD8: =MID($O8,AD$1,4) -> 1010 | AE8: =MID($O8,AE$1,4) -> 1101 | AF8: =MID($O8,AF$1,4) -> 0010 | AG8: =MID($O8,AG$1,4) -> 1101 | AH8: =MID($O8,AH$1,4) -> 1101 | ... AL8: =MID($O8,AL$1,4) -> 0000 | AM8: =BIN2HEX(AA8) -> 7 | AN8: =BIN2HEX(AB8) -> 0 | AO8: =BIN2HEX(AC8) -> 8 | AP8: =BIN2HEX(AD8) -> A | AQ8: =BIN2HEX(AE8) -> D | AR8: =BIN2HEX(AF8) -> 2 | AS8: =BIN2HEX(AG8) -> D | AT8: =BIN2HEX(AH8) -> D | ... AX8: =BIN2HEX(AL8) -> 0
